Workbook

Sheet Crude Oil
A1: Date | B1: Crude Oil, Average ($/bbl) | C1: Rendement | D1: Ecart-Type
A2: 21916 | B2: 1.6300001 | C2: 0 | D2: =STDEV(#REF!) -> #REF!
A3: 21947 | B3: 1.6300001 | C3: =(B3/B2)-1 -> 0 | D3: =STDEV(#REF!) -> #REF!
A4: 21976 | B4: 1.6300001 | C4: =(B4/B3)-1 -> 0 | D4: =STDEV(#REF!) -> #REF!
A5: 22007 | B5: 1.6300001 | C5: =(B5/B4)-1 -> 0 | D5: =STDEV(#REF!) -> #REF!
A6: 22037 | B6: 1.6300001 | C6: =(B6/B5)-1 -> 0 | D6: =STDEV(#REF!) -> #REF!
A7: 22068 | B7: 1.6300001 | C7: =(B7/B6)-1 -> 0 | D7: =STDEV(#REF!) -> #REF!
A8: 22098 | B8: 1.6300001 | C8: =(B8/B7)-1 -> 0 | D8: =STDEV(#REF!) -> #REF!
A9: 22129 | B9: 1.6300001 | C9: =(B9/B8)-1 -> 0 | D9: =STDEV(#REF!) -> #REF!
A10: 22160 | B10: 1.6300001 | C10: =(B10/B9)-1 -> 0 | D10: =STDEV(#REF!) -> #REF!
A11: 22190 | B11: 1.6300001 | C11: =(B11/B10)-1 -> 0 | D11: =STDEV(#REF!) -> #REF!
A12: 22221 | B12: 1.6300001 | C12: =(B12/B11)-1 -> 0 | D12: =STDEV(#REF!) -> #REF!
A13: 22251 | B13: 1.6300001 | C13: =(B13/B12)-1 -> 0 | D13: =STDEV(#REF!) -> #REF!
A14: 22282 | B14: 1.57 | C14: =(B14/B13)-1 -> -0.036809884 | D14: =STDEV(#REF!) -> #REF!
... A23: 22555 | B23: 1.57 | C23: =(B23/B22)-1 -> 0 | D23: =STDEV(#REF!) -> #REF!
A24: 22586 | B24: 1.57 | C24: =(B24/B23)-1 -> 0 | D24: =STDEV(C1:C24) -> 0.0076753913
A25: 22616 | B25: 1.57 | C25: =(B25/B24)-1 -> 0 | D25: =STDEV(C2:C25) -> 0.007513786
A26: 22647 | B26: 1.52 | C26: =(B26/B25)-1 -> -0.031847134 | D26: =STDEV(C3:C26) -> 0.0097195449
A27: 22678 | B27: 1.52 | C27: =(B27/B26)-1 -> 0 | D27: =STDEV(C4:C27) -> 0.0097195449
A28: 22706 | B28: 1.52 | C28: =(B28/B27)-1 -> 0 | D28: =STDEV(C5:C28) -> 0.0097195449
A29: 22737 | B29: 1.52 | C29: =(B29/B28)-1 -> 0 | D29: =STDEV(C6:C29) -> 0.0097195449
A30: 22767 | B30: 1.52 | C30: =(B30/B29)-1 -> 0 | D30: =STDEV(C7:C30) -> 0.0097195449
A31: 22798 | B31: 1.52 | C31: =(B31/B30)-1 -> 0 | D31: =STDEV(C8:C31) -> 0.0097195449
A32: 22828 | B32: 1.52 | C32: =(B32/B31)-1 -> 0 | D32: =STDEV(C9:C32) -> 0.0097195449
A33: 22859 | B33: 1.52 | C33: =(B33/B32)-1 -> 0 | D33: =STDEV(C10:C33) -> 0.0097195449
A34: 22890 | B34: 1.52 | C34: =(B34/B33)-1 -> 0 | D34: =STDEV(C11:C34) -> 0.0097195449
A35: 22920 | B35: 1.52 | C35: =(B35/B34)-1 -> 0 | D35: =STDEV(C12:C35) -> 0.0097195449
... A793: 45992 | B793: 60.88 | C793: =(B793/B792)-1 -> -0.023362512 | D793: =STDEV(C770:C793) -> 0.048633612

Sheet data
A1: Date | B1: Crude Oil, Average ($/bbl)
A2: 36526 | B2: 25.31
A3: 36557 | B3: 27.22
A4: 36586 | B4: 27.49
A5: 36617 | B5: 23.47
A6: 36647 | B6: 27.19
A7: 36678 | B7: 29.62
A8: 36708 | B8: 28.18
A9: 36739 | B9: 29.26
A10: 36770 | B10: 32.08
A11: 36800 | B11: 31.4
A12: 36831 | B12: 32.33
A13: 36861 | B13: 25.2
... A313: 45992 | B313: 60.88

Sheet Statistiques
A1: Date | B1: Crude Oil, Average ($/bbl) | C1: Moyenne | D1: Min | E1: Max | F1: Rendement | G1: Ecart-Type | H1: Volatilité annuelle | I1: Log-Return
A2: 36526 | B2: 25.31 | C2: =AVERAGE($B$2:$B$312) -> 65.033556 | D2: =MIN($B$2:$B$312) -> 18.519789 | E2: =MAX($B$2:$B$312) -> 132.82518 | F2: 0 | G2: ='Crude Oil'!D482 -> 0.09534903 | H2: =G2*SQRT(12) -> 0.33029873 | I2: =0% -> 0
A3: 36557 | B3: 27.220967 | C3: =AVERAGE($B$2:$B$312) -> 65.033556 | D3: =MIN($B$2:$B$312) -> 18.519789 | E3: =MAX($B$2:$B$312) -> 132.82518 | F3: =(B3/B2)-1 -> 0.075502436 | G3: ='Crude Oil'!D483 -> 0.094024239 | H3: =G3*SQRT(12) -> 0.32570952 | I3: =LN(B3/B2) -> 0.072787935
A4: 36586 | B4: 27.49 | C4: =AVERAGE($B$2:$B$312) -> 65.033556 | D4: =MIN($B$2:$B$312) -> 18.519789 | E4: =MAX($B$2:$B$312) -> 132.82518 | F4: =(B4/B3)-1 -> 0.009883313 | G4: ='Crude Oil'!D484 -> 0.091681653 | H4: =G4*SQRT(12) -> 0.31759456 | I4: =LN(B4/B3) -> 0.0098347925
A5: 36617 | B5: 23.47 | C5: =AVERAGE($B$2:$B$312) -> 65.033556 | D5: =MIN($B$2:$B$312) -> 18.519789 | E5: =MAX($B$2:$B$312) -> 132.82518 | F5: =(B5/B4)-1 -> -0.14623499 | G5: ='Crude Oil'!D485 -> 0.098888573 | H5: =G5*SQRT(12) -> 0.34256006 | I5: =LN(B5/B4) -> -0.15809929
A6: 36647 | B6: 27.186667 | C6: =AVERAGE($B$2:$B$312) -> 65.033556 | D6: =MIN($B$2:$B$312) -> 18.519789 | E6: =MAX($B$2:$B$312) -> 132.82518 | F6: =(B6/B5)-1 -> 0.15835819 | G6: ='Crude Oil'!D486 -> 0.10241097 | H6: =G6*SQRT(12) -> 0.35476202 | I6: =LN(B6/B5) -> 0.14700365
A7: 36678 | B7: 29.620767 | C7: =AVERAGE($B$2:$B$312) -> 65.033556 | D7: =MIN($B$2:$B$312) -> 18.519789 | E7: =MAX($B$2:$B$312) -> 132.82518 | F7: =(B7/B6)-1 -> 0.089532859 | G7: ='Crude Oil'!D487 -> 0.098305388 | H7: =G7*SQRT(12) -> 0.34053985 | I7: =LN(B7/B6) -> 0.085749035
A8: 36708 | B8: 28.176667 | C8: =AVERAGE($B$2:$B$312) -> 65.033556 | D8: =MIN($B$2:$B$312) -> 18.519789 | E8: =MAX($B$2:$B$312) -> 132.82518 | F8: =(B8/B7)-1 -> -0.048752958 | G8: ='Crude Oil'!D488 -> 0.099917835 | H8: =G8*SQRT(12) -> 0.34612553 | I8: =LN(B8/B7) -> -0.04998148
A9: 36739 | B9: 29.2629 | C9: =AVERAGE($B$2:$B$312) -> 65.033556 | D9: =MIN($B$2:$B$312) -> 18.519789 | E9: =MAX($B$2:$B$312) -> 132.82518 | F9: =(B9/B8)-1 -> 0.03855081 | G9: ='Crude Oil'!D489 -> 0.099227812 | H9: =G9*SQRT(12) -> 0.34373522 | I9: =LN(B9/B8) -> 0.03782629
A10: 36770 | B10: 32.082833 | C10: =AVERAGE($B$2:$B$312) -> 65.033556 | D10: =MIN($B$2:$B$312) -> 18.519789 | E10: =MAX($B$2:$B$312) -> 132.82518 | F10: =(B10/B9)-1 -> 0.096365478 | G10: ='Crude Oil'!D490 -> 0.09899055 | H10: =G10*SQRT(12) -> 0.34291332 | I10: =LN(B10/B9) -> 0.092000598
A11: 36800 | B11: 31.400167 | C11: =AVERAGE($B$2:$B$312) -> 65.033556 | D11: =MIN($B$2:$B$312) -> 18.519789 | E11: =MAX($B$2:$B$312) -> 132.82518 | F11: =(B11/B10)-1 -> -0.021278254 | G11: ='Crude Oil'!D491 -> 0.098433302 | H11: =G11*SQRT(12) -> 0.34098296 | I11: =LN(B11/B10) -> -0.021507899
A12: 36831 | B12: 32.331 | C12: =AVERAGE($B$2:$B$312) -> 65.033556 | D12: =MIN($B$2:$B$312) -> 18.519789 | E12: =MAX($B$2:$B$312) -> 132.82518 | F12: =(B12/B11)-1 -> 0.029644216 | G12: ='Crude Oil'!D492 -> 0.093506269 | H12: =G12*SQRT(12) -> 0.32391522 | I12: =LN(B12/B11) -> 0.029213322
A13: 36861 | B13: 25.204667 | C13: =AVERAGE($B$2:$B$312) -> 65.033556 | D13: =MIN($B$2:$B$312) -> 18.519789 | E13: =MAX($B$2:$B$312) -> 132.82518 | F13: =(B13/B12)-1 -> -0.22041797 | G13: ='Crude Oil'!D493 -> 0.10278819 | H13: =G13*SQRT(12) -> 0.35606874 | I13: =LN(B13/B12) -> -0.24899736
A14: 36892 | B14: 25.957273 | C14: =AVERAGE($B$2:$B$312) -> 65.033556 | D14: =MIN($B$2:$B$312) -> 18.519789 | E14: =MAX($B$2:$B$312) -> 132.82518 | F14: =(B14/B13)-1 -> 0.02985979 | G14: ='Crude Oil'!D494 -> 0.10209962 | H14: =G14*SQRT(12) -> 0.35368344 | I14: =LN(B14/B13) -> 0.029422667
... A312: 45962 | B312: 62.336333 | C312: =AVERAGE($B$2:$B$312) -> 65.033556 | D312: =MIN($B$2:$B$312) -> 18.519789 | E312: =MAX($B$2:$B$312) -> 132.82518 | F312: =(B312/B311)-1 -> -0.011167454 | G312: ='Crude Oil'!D792 -> 0.050146359 | H312: =G312*SQRT(12) -> 0.17371208 | I312: =LN(B312/B311) -> -0.011230278
A313: 45992 | B313: 60.88 | C313: =AVERAGE($B$2:$B$312) -> 65.033556 | D313: =MIN($B$2:$B$312) -> 18.519789 | E313: =MAX($B$2:$B$312) -> 132.82518 | F313: =(B313/B312)-1 -> -0.023362512 | G313: ='Crude Oil'!D793 -> 0.048633612 | H313: =G313*12 -> 0.58360334 | I313: =LN(B313/B312) -> -0.023639742

Sheet Call Option Avril 2026
D2: Time To maturity | E2: =DATEDIF(D3,D4,"d") -> 296 | F2: =E2/365 -> 0.8109589
D3: 45999 | H3: Volatilité | I3: 0.21
D4: 46295 | H4: Spot | I4: 6.1325 | K4: Prime | L4: =AVERAGE(H12:H2012) -> 0.4636659
H5: Strike | I5: 6.1325
H6: Seed | I6: 7
D9: Moyenne
D10: Ecart-Type
E11: Uniforme | F11: Normale (0,1) | G11: Futur September 2026 | H11: Payoff du call
D12: 1 | E12: =SQRT($I$6)*D12-INT(SQRT($I$6)*D12) -> 0.64575131 | F12: =_xlfn.NORM.S.INV(E12) -> 0.37387492 | G12: =$I$4*EXP(-$I$3*$I$3/2*$F$2)*EXP($I$3*SQRT($F$2)*F12) -> 6.4651423 | H12: =MAX((G12-$I$5),0) -> 0.33264232 | K12: Volatilité | L12: Primes
D13: 2 | E13: =SQRT($I$6)*D13-INT(SQRT($I$6)*D13) -> 0.29150262 | F13: =_xlfn.NORM.S.INV(E13) -> -0.5490003 | G13: =$I$4*EXP(-$I$3*$I$3/2*$F$2)*EXP($I$3*SQRT($F$2)*F13) -> 5.4297788 | H13: =MAX((G13-$I$5),0) -> 0 | K13: 0.1 | L13: 0.22098456
D14: 3 | E14: =SQRT($I$6)*D14-INT(SQRT($I$6)*D14) -> 0.93725393 | F14: =_xlfn.NORM.S.INV(E14) -> 1.5321228 | G14: =$I$4*EXP(-$I$3*$I$3/2*$F$2)*EXP($I$3*SQRT($F$2)*F14) -> 8.0483203 | H14: =MAX((G14-$I$5),0) -> 1.9158203 | K14: 0.2 | L14: 0.44163525
D15: 4 | E15: =SQRT($I$6)*D15-INT(SQRT($I$6)*D15) -> 0.58300524 | F15: =_xlfn.NORM.S.INV(E15) -> 0.20958766 | G15: =$I$4*EXP(-$I$3*$I$3/2*$F$2)*EXP($I$3*SQRT($F$2)*F15) -> 6.2673672 | H15: =MAX((G15-$I$5),0) -> 0.13486719 | K15: 0.3 | L15: 0.66151249
D16: 5 | E16: =SQRT($I$6)*D16-INT(SQRT($I$6)*D16) -> 0.22875656 | F16: =_xlfn.NORM.S.INV(E16) -> -0.74294809 | G16: =$I$4*EXP(-$I$3*$I$3/2*$F$2)*EXP($I$3*SQRT($F$2)*F16) -> 5.2342343 | H16: =MAX((G16-$I$5),0) -> 0 | K16: 0.4 | L16: 0.88019117
D17: 6 | E17: =SQRT($I$6)*D17-INT(SQRT($I$6)*D17) -> 0.87450787 | F17: =_xlfn.NORM.S.INV(E17) -> 1.147962 | G17: =$I$4*EXP(-$I$3*$I$3/2*$F$2)*EXP($I$3*SQRT($F$2)*F17) -> 7.4843491 | H17: =MAX((G17-$I$5),0) -> 1.3518491 | K17: 0.5 | L17: 1.0972712
D18: 7 | E18: =SQRT($I$6)*D18-INT(SQRT($I$6)*D18) -> 0.52025918 | F18: =_xlfn.NORM.S.INV(E18) -> 0.050804073 | G18: =$I$4*EXP(-$I$3*$I$3/2*$F$2)*EXP($I$3*SQRT($F$2)*F18) -> 6.0819691 | H18: =MAX((G18-$I$5),0) -> 0 | K18: 0.6 | L18: 1.3123439
D19: 8 | E19: =SQRT($I$6)*D19-INT(SQRT($I$6)*D19) -> 0.16601049 | F19: =_xlfn.NORM.S.INV(E19) -> -0.97005119 | G19: =$I$4*EXP(-$I$3*$I$3/2*$F$2)*EXP($I$3*SQRT($F$2)*F19) -> 5.014194 | H19: =MAX((G19-$I$5),0) -> 0 | K19: 0.7 | L19: 1.5249246
D20: 9 | E20: =SQRT($I$6)*D20-INT(SQRT($I$6)*D20) -> 0.8117618 | F20: =_xlfn.NORM.S.INV(E20) -> 0.88440727 | G20: =$I$4*EXP(-$I$3*$I$3/2*$F$2)*EXP($I$3*SQRT($F$2)*F20) -> 7.1204629 | H20: =MAX((G20-$I$5),0) -> 0.98796291 | K20: 0.8 | L20: 1.7346719
D21: 10 | E21: =SQRT($I$6)*D21-INT(SQRT($I$6)*D21) -> 0.45751311 | F21: =_xlfn.NORM.S.INV(E21) -> -0.10670096 | G21: =$I$4*EXP(-$I$3*$I$3/2*$F$2)*EXP($I$3*SQRT($F$2)*F21) -> 5.9034825 | H21: =MAX((G21-$I$5),0) -> 0 | K21: 0.9 | L21: 1.9411885
D22: 11 | E22: =SQRT($I$6)*D22-INT(SQRT($I$6)*D22) -> 0.10326442 | F22: =_xlfn.NORM.S.INV(E22) -> -1.2631679 | G22: =$I$4*EXP(-$I$3*$I$3/2*$F$2)*EXP($I$3*SQRT($F$2)*F22) -> 4.7438111 | H22: =MAX((G22-$I$5),0) -> 0
D23: 12 | E23: =SQRT($I$6)*D23-INT(SQRT($I$6)*D23) -> 0.74901573 | F23: =_xlfn.NORM.S.INV(E23) -> 0.67139562 | G23: =$I$4*EXP(-$I$3*$I$3/2*$F$2)*EXP($I$3*SQRT($F$2)*F23) -> 6.8393296 | H23: =MAX((G23-$I$5),0) -> 0.70682959
D24: 13 | E24: =SQRT($I$6)*D24-INT(SQRT($I$6)*D24) -> 0.39476704 | F24: =_xlfn.NORM.S.INV(E24) -> -0.26691567 | G24: =$I$4*EXP(-$I$3*$I$3/2*$F$2)*EXP($I$3*SQRT($F$2)*F24) -> 5.7272984 | H24: =MAX((G24-$I$5),0) -> 0
D25: 14 | E25: =SQRT($I$6)*D25-INT(SQRT($I$6)*D25) -> 0.040518355 | F25: =_xlfn.NORM.S.INV(E25) -> -1.7447023 | G25: =$I$4*EXP(-$I$3*$I$3/2*$F$2)*EXP($I$3*SQRT($F$2)*F25) -> 4.330907 | H25: =MAX((G25-$I$5),0) -> 0
D26: 15 | E26: =SQRT($I$6)*D26-INT(SQRT($I$6)*D26) -> 0.68626967 | F26: =_xlfn.NORM.S.INV(E26) -> 0.48530407 | G26: =$I$4*EXP(-$I$3*$I$3/2*$F$2)*EXP($I$3*SQRT($F$2)*F26) -> 6.6028251 | H26: =MAX((G26-$I$5),0) -> 0.47032507
D27: 16 | E27: =SQRT($I$6)*D27-INT(SQRT($I$6)*D27) -> 0.33202098 | F27: =_xlfn.NORM.S.INV(E27) -> -0.43433946 | G27: =$I$4*EXP(-$I$3*$I$3/2*$F$2)*EXP($I$3*SQRT($F$2)*F27) -> 5.5488024 | H27: =MAX((G27-$I$5),0) -> 0
D28: 17 | E28: =SQRT($I$6)*D28-INT(SQRT($I$6)*D28) -> 0.97777229 | F28: =_xlfn.NORM.S.INV(E28) -> 2.0097711 | G28: =$I$4*EXP(-$I$3*$I$3/2*$F$2)*EXP($I$3*SQRT($F$2)*F28) -> 8.8091624 | H28: =MAX((G28-$I$5),0) -> 2.6766624
D29: 18 | E29: =SQRT($I$6)*D29-INT(SQRT($I$6)*D29) -> 0.6235236 | F29: =_xlfn.NORM.S.INV(E29) -> 0.31474826 | G29: =$I$4*EXP(-$I$3*$I$3/2*$F$2)*EXP($I$3*SQRT($F$2)*F29) -> 6.3932547 | H29: =MAX((G29-$I$5),0) -> 0.26075466
D30: 19 | E30: =SQRT($I$6)*D30-INT(SQRT($I$6)*D30) -> 0.26927491 | F30: =_xlfn.NORM.S.INV(E30) -> -0.61500742 | G30: =$I$4*EXP(-$I$3*$I$3/2*$F$2)*EXP($I$3*SQRT($F$2)*F30) -> 5.3624216 | H30: =MAX((G30-$I$5),0) -> 0
D31: 20 | E31: =SQRT($I$6)*D31-INT(SQRT($I$6)*D31) -> 0.91502622 | F31: =_xlfn.NORM.S.INV(E31) -> 1.3723723 | G31: =$I$4*EXP(-$I$3*$I$3/2*$F$2)*EXP($I$3*SQRT($F$2)*F31) -> 7.808811 | H31: =MAX((G31-$I$5),0) -> 1.676311
D32: 21 | E32: =SQRT($I$6)*D32-INT(SQRT($I$6)*D32) -> 0.56077753 | F32: =_xlfn.NORM.S.INV(E32) -> 0.15294083 | G32: =$I$4*EXP(-$I$3*$I$3/2*$F$2)*EXP($I$3*SQRT($F$2)*F32) -> 6.2005858 | H32: =MAX((G32-$I$5),0) -> 0.068085824
D33: 22 | E33: =SQRT($I$6)*D33-INT(SQRT($I$6)*D33) -> 0.20652884 | F33: =_xlfn.NORM.S.INV(E33) -> -0.81852463 | G33: =$I$4*EXP(-$I$3*$I$3/2*$F$2)*EXP($I$3*SQRT($F$2)*F33) -> 5.1599565 | H33: =MAX((G33-$I$5),0) -> 0
... D2011: 2000 | E2011: =SQRT($I$6)*D2011-INT(SQRT($I$6)*D2011) -> 0.50262213 | F2011: =_xlfn.NORM.S.INV(E2011) -> 0.0065727505 | G2011: =$I$4*EXP(-$I$3*$I$3/2*$F$2)*EXP($I$3*SQRT($F$2)*F2011) -> 6.0313076 | H2011: =MAX((G2011-$I$5),0) -> 0
G2013: =AVERAGE(G12:G2011) -> 6.1363294

Sheet Call Option 2026 2027
A1: 8.4
A2: 7.6083333 | D2: Seed | E2: 7 | G2: Spot | H2: 8.4 | M2: Date de pricing | N2: 45999 | P2: Volatilité | Q2: 0.21 | AS2: =AVERAGE(AS8:AS2006) -> 8.4076109
A3: 6.8183333
A4: 6.0266667 | B4: Payoff | F4: =AVERAGE(F8:F2006) -> 2.6515968 | H4: =AVERAGE(H8:H2006) -> 2.6523858 | J4: =AVERAGE(J8:J2006) -> 2.652907 | L4: =AVERAGE(L8:L2006) -> 2.6533829 | N4: =AVERAGE(N8:N2006) -> 2.6540213 | P4: =AVERAGE(P8:P2006) -> 2.6551569 | R4: =AVERAGE(R8:R2006) -> 2.656816 | T4: =AVERAGE(T8:T2006) -> 2.6591785 | V4: =AVERAGE(V8:V2006) -> 2.6621889 | X4: =AVERAGE(X8:X2006) -> 2.6656355 | Z4: =AVERAGE(Z8:Z2006) -> 2.6697624 | AB4: =AVERAGE(AB8:AB2006) -> 2.6742592 | AD4: =AVERAGE(AD8:AD2006) -> 2.6793702 | AF4: =AVERAGE(AF8:AF2006) -> 2.6849091 | AH4: =AVERAGE(AH8:AH2006) -> 2.6902255 | AJ4: =AVERAGE(AJ8:AJ2006) -> 2.6964012 | AL4: =AVERAGE(AL8:AL2006) -> 2.7026657 | AN4: =AVERAGE(AN8:AN2006) -> 2.7093863 | AP4: =AVERAGE(AP8:AP2006) -> 2.716088 | AR4: =AVERAGE(AR8:AR2006) -> 2.7232148 | AT4: =AVERAGE(AT8:AT2006) -> 2.7305225
A5: 5.8758333 | B5: Time To maturity | E5: 46023 | F5: 46023 | G5: 46054 | H5: 46054 | I5: 46082 | J5: 46082 | K5: 46113 | L5: 46113 | M5: 46143 | N5: 46143 | O5: 46174 | P5: 46174 | Q5: 46204 | R5: 46204 | S5: 46235 | T5: 46235 | U5: 46266 | V5: 46266 | W5: 46296 | X5: 46296 | Y5: 46327 | Z5: 46327 | AA5: 46357 | AB5: 46357 | AC5: 46388 | AD5: 46388 | AE5: 46419 | AF5: 46419 | AG5: 46447 | AH5: 46447 | AI5: 46478 | AJ5: 46478 | AK5: 46508 | AL5: 46508 | AM5: 46539 | AN5: 46539 | AO5: 46569 | AP5: 46569 | AQ5: 46600 | AR5: 46600 | AS5: 46631 | AT5: 46631
A6: 5.725 | B6: T | E6: =DATEDIF($N$2,E5,"d") /365 -> 0.065753425 | G6: =DATEDIF($N$2,G5,"d") /365 -> 0.15068493 | I6: =DATEDIF($N$2,I5,"d") /365 -> 0.22739726 | K6: =DATEDIF($N$2,K5,"d") /365 -> 0.31232877 | M6: =DATEDIF($N$2,M5,"d") /365 -> 0.39452055 | O6: =DATEDIF($N$2,O5,"d") /365 -> 0.47945205 | Q6: =DATEDIF($N$2,Q5,"d") /365 -> 0.56164384 | S6: =DATEDIF($N$2,S5,"d") /365 -> 0.64657534 | U6: =DATEDIF($N$2,U5,"d") /365 -> 0.73150685 | W6: =DATEDIF($N$2,W5,"d") /365 -> 0.81369863 | Y6: =DATEDIF($N$2,Y5,"d") /365 -> 0.89863014 | AA6: =DATEDIF($N$2,AA5,"d") /365 -> 0.98082192 | AC6: =DATEDIF($N$2,AC5,"d") /365 -> 1.0657534 | AE6: =DATEDIF($N$2,AE5,"d") /365 -> 1.1506849 | AG6: =DATEDIF($N$2,AG5,"d") /365 -> 1.2273973 | AI6: =DATEDIF($N$2,AI5,"d") /365 -> 1.3123288 | AK6: =DATEDIF($N$2,AK5,"d") /365 -> 1.3945205 | AM6: =DATEDIF($N$2,AM5,"d") /365 -> 1.4794521 | AO6: =DATEDIF($N$2,AO5,"d") /365 -> 1.5616438 | AQ6: =DATEDIF($N$2,AQ5,"d") /365 -> 1.6465753 | AS6: =DATEDIF($N$2,AS5,"d") /365 -> 1.7315068
A7: 5.6666667 | B7: Simulator | C7: Uniforme | D7: Normale(0,1) | F7: 5.75 | H7: 5.75 | J7: 5.75 | L7: 5.75 | N7: 5.75 | P7: 5.75 | R7: 5.75 | T7: 5.75 | V7: 5.75 | X7: 5.75 | Z7: 5.75 | AB7: 5.75 | AD7: 5.75 | AF7: 5.75 | AH7: 5.75 | AJ7: 5.75 | AL7: 5.75 | AN7: 5.75 | AP7: 5.75 | AR7: 5.75 | AT7: 5.75
A8: 5.6075 | B8: 1 | C8: =SQRT($E$2)*B8-INT(SQRT($E$2)*B8) -> 0.64575131 | D8: =_xlfn.NORM.S.INV(C8) -> 0.37387492 | E8: =$H$2*EXP(-$Q$2*$Q$2/2*E$6)*EXP($Q$2*SQRT(E$6)*$D8) -> 8.5584121 | F8: =MAX((E8-$F$7),0) -> 2.8084121 | G8: =$H$2*EXP(-$Q$2*$Q$2/2*G$6)*EXP($Q$2*SQRT(G$6)*$D8) -> 8.6312271 | H8: =MAX(0,(G8-$H$7)) -> 2.8812271 | I8: =$H$2*EXP(-$Q$2*$Q$2/2*I$6)*EXP($Q$2*SQRT(I$6)*$D8) -> 8.6768434 | J8: =MAX(0,(I8-$J$7)) -> 2.9268434 | K8: =$H$2*EXP(-$Q$2*$Q$2/2*K$6)*EXP($Q$2*SQRT(K$6)*$D8) -> 8.7165485 | L8: =MAX(0,(K8-$L$7)) -> 2.9665485 | M8: =$H$2*EXP(-$Q$2*$Q$2/2*M$6)*EXP($Q$2*SQRT(M$6)*$D8) -> 8.7481976 | N8: =MAX(0,(M8-$N$7)) -> 2.9981976 | O8: =$H$2*EXP(-$Q$2*$Q$2/2*O$6)*EXP($Q$2*SQRT(O$6)*$D8) -> 8.7760344 | P8: =MAX(0,(O8-$P$7)) -> 3.0260344 | Q8: =$H$2*EXP(-$Q$2*$Q$2/2*Q$6)*EXP($Q$2*SQRT(Q$6)*$D8) -> 8.7994386 | R8: =MAX((Q8-$R$7),0) -> 3.0494386 | S8: =$H$2*EXP(-$Q$2*$Q$2/2*S$6)*EXP($Q$2*SQRT(S$6)*$D8) -> 8.8207556 | T8: =MAX(0,(S8-$T$7)) -> 3.0707556 | U8: =$H$2*EXP(-$Q$2*$Q$2/2*U$6)*EXP($Q$2*SQRT(U$6)*$D8) -> 8.8397036 | V8: =MAX(0,(U8-$V$7)) -> 3.0897036 | W8: =$H$2*EXP(-$Q$2*$Q$2/2*W$6)*EXP($Q$2*SQRT(W$6)*$D8) -> 8.8561591 | X8: =MAX(0,(W8-$X$7)) -> 3.1061591 | Y8: =$H$2*EXP(-$Q$2*$Q$2/2*Y$6)*EXP($Q$2*SQRT(Y$6)*$D8) -> 8.8715087 | Z8: =MAX(0,(Y8-$Z$7)) -> 3.1215087 | AA8: =$H$2*EXP(-$Q$2*$Q$2/2*AA$6)*EXP($Q$2*SQRT(AA$6)*$D8) -> 8.8849763 | AB8: =MAX(0,(AA8-$AB$7)) -> 3.1349763 | AC8: =$H$2*EXP(-$Q$2*$Q$2/2*AC$6)*EXP($Q$2*SQRT(AC$6)*$D8) -> 8.8976372 | AD8: =MAX(0,(AC8-$AD$7)) -> 3.1476372 | AE8: =$H$2*EXP(-$Q$2*$Q$2/2*AE$6)*EXP($Q$2*SQRT(AE$6)*$D8) -> 8.9091672 | AF8: =MAX((AE8-$AF$7),0) -> 3.1591672 | AG8: =$H$2*EXP(-$Q$2*$Q$2/2*AG$6)*EXP($Q$2*SQRT(AG$6)*$D8) -> 8.9187104 | AH8: =MAX((AG8-$AH$7),0) -> 3.1687104 | AI8: =$H$2*EXP(-$Q$2*$Q$2/2*AI$6)*EXP($Q$2*SQRT(AI$6)*$D8) -> 8.928405 | AJ8: =MAX(0,(AI8-$AJ$7)) -> 3.178405 | AK8: =$H$2*EXP(-$Q$2*$Q$2/2*AK$6)*EXP($Q$2*SQRT(AK$6)*$D8) -> 8.9369937 | AL8: =MAX(0,(AK8-$AL$7)) -> 3.1869937 | AM8: =$H$2*EXP(-$Q$2*$Q$2/2*AM$6)*EXP($Q$2*SQRT(AM$6)*$D8) -> 8.9451205 | AN8: =MAX(0,(AM8-$AN$7)) -> 3.1951205 | AO8: =$H$2*EXP(-$Q$2*$Q$2/2*AO$6)*EXP($Q$2*SQRT(AO$6)*$D8) -> 8.9523202 | AP8: =MAX(0,(AO8-$AP$7)) -> 3.2023202 | AQ8: =$H$2*EXP(-$Q$2*$Q$2/2*AQ$6)*EXP($Q$2*SQRT(AQ$6)*$D8) -> 8.9591264 | AR8: =MAX(0,(AQ8-$AR$7)) -> 3.2091264 | AS8: =$H$2*EXP(-$Q$2*$Q$2/2*AS$6)*EXP($Q$2*SQRT(AS$6)*$D8) -> 8.9653365 | AT8: =MAX(0,(AS8-$AT$7)) -> 3.2153365
A9: 5.5553333 | B9: 2 | C9: =SQRT($E$2)*B9-INT(SQRT($E$2)*B9) -> 0.29150262 | D9: =_xlfn.NORM.S.INV(C9) -> -0.5490003 | E9: =$H$2*EXP(-$Q$2*$Q$2/2*E$6)*EXP($Q$2*SQRT(E$6)*$D9) -> 8.1434886 | F9: =MAX((E9-$F$7),0) -> 2.3934886 | G9: =$H$2*EXP(-$Q$2*$Q$2/2*G$6)*EXP($Q$2*SQRT(G$6)*$D9) -> 8.0057147 | H9: =MAX(0,(G9-$H$7)) -> 2.2557147 | I9: =$H$2*EXP(-$Q$2*$Q$2/2*I$6)*EXP($Q$2*SQRT(I$6)*$D9) -> 7.910889 | J9: =MAX(0,(I9-$J$7)) -> 2.160889 | K9: =$H$2*EXP(-$Q$2*$Q$2/2*K$6)*EXP($Q$2*SQRT(K$6)*$D9) -> 7.8217899 | L9: =MAX(0,(K9-$L$7)) -> 2.0717899 | M9: =$H$2*EXP(-$Q$2*$Q$2/2*M$6)*EXP($Q$2*SQRT(M$6)*$D9) -> 7.745545 | N9: =MAX(0,(M9-$N$7)) -> 1.995545 | O9: =$H$2*EXP(-$Q$2*$Q$2/2*O$6)*EXP($Q$2*SQRT(O$6)*$D9) -> 7.6739394 | P9: =MAX(0,(O9-$P$7)) -> 1.9239394 | Q9: =$H$2*EXP(-$Q$2*$Q$2/2*Q$6)*EXP($Q$2*SQRT(Q$6)*$D9) -> 7.6098674 | R9: =MAX((Q9-$R$7),0) -> 1.8598674 | S9: =$H$2*EXP(-$Q$2*$Q$2/2*S$6)*EXP($Q$2*SQRT(S$6)*$D9) -> 7.5479053 | T9: =MAX(0,(S9-$T$7)) -> 1.7979053 | U9: =$H$2*EXP(-$Q$2*$Q$2/2*U$6)*EXP($Q$2*SQRT(U$6)*$D9) -> 7.4894585 | V9: =MAX(0,(U9-$V$7)) -> 1.7394585 | W9: =$H$2*EXP(-$Q$2*$Q$2/2*W$6)*EXP($Q$2*SQRT(W$6)*$D9) -> 7.4356944 | X9: =MAX(0,(W9-$X$7)) -> 1.6856944 | Y9: =$H$2*EXP(-$Q$2*$Q$2/2*Y$6)*EXP($Q$2*SQRT(Y$6)*$D9) -> 7.382604 | Z9: =MAX(0,(Y9-$Z$7)) -> 1.632604 | AA9: =$H$2*EXP(-$Q$2*$Q$2/2*AA$6)*EXP($Q$2*SQRT(AA$6)*$D9) -> 7.3332983 | AB9: =MAX(0,(AA9-$AB$7)) -> 1.5832983 | AC9: =$H$2*EXP(-$Q$2*$Q$2/2*AC$6)*EXP($Q$2*SQRT(AC$6)*$D9) -> 7.2842302 | AD9: =MAX(0,(AC9-$AD$7)) -> 1.5342302 | AE9: =$H$2*EXP(-$Q$2*$Q$2/2*AE$6)*EXP($Q$2*SQRT(AE$6)*$D9) -> 7.2368604 | AF9: =MAX((AE9-$AF$7),0) -> 1.4868604 | AG9: =$H$2*EXP(-$Q$2*$Q$2/2*AG$6)*EXP($Q$2*SQRT(AG$6)*$D9) -> 7.1953867 | AH9: =MAX((AG9-$AH$7),0) -> 1.4453867 | AI9: =$H$2*EXP(-$Q$2*$Q$2/2*AI$6)*EXP($Q$2*SQRT(AI$6)*$D9) -> 7.1507848 | AJ9: =MAX(0,(AI9-$AJ$7)) -> 1.4007848 | AK9: =$H$2*EXP(-$Q$2*$Q$2/2*AK$6)*EXP($Q$2*SQRT(AK$6)*$D9) -> 7.1088231 | AL9: =MAX(0,(AK9-$AL$7)) -> 1.3588231 | AM9: =$H$2*EXP(-$Q$2*$Q$2/2*AM$6)*EXP($Q$2*SQRT(AM$6)*$D9) -> 7.0665992 | AN9: =MAX(0,(AM9-$AN$7)) -> 1.3165992 | AO9: =$H$2*EXP(-$Q$2*$Q$2/2*AO$6)*EXP($Q$2*SQRT(AO$6)*$D9) -> 7.0267505 | AP9: =MAX(0,(AO9-$AP$7)) -> 1.2767505 | AQ9: =$H$2*EXP(-$Q$2*$Q$2/2*AQ$6)*EXP($Q$2*SQRT(AQ$6)*$D9) -> 6.9865419 | AR9: =MAX(0,(AQ9-$AR$7)) -> 1.2365419 | AS9: =$H$2*EXP(-$Q$2*$Q$2/2*AS$6)*EXP($Q$2*SQRT(AS$6)*$D9) -> 6.9472476 | AT9: =MAX(0,(AS9-$AT$7)) -> 1.1972476
A10: 5.5033333 | B10: 3 | C10: =SQRT($E$2)*B10-INT(SQRT($E$2)*B10) -> 0.93725393 | D10: =_xlfn.NORM.S.INV(C10) -> 1.5321228 | E10: =$H$2*EXP(-$Q$2*$Q$2/2*E$6)*EXP($Q$2*SQRT(E$6)*$D10) -> 9.1092036 | F10: =MAX((E10-$F$7),0) -> 3.3592036 | G10: =$H$2*EXP(-$Q$2*$Q$2/2*G$6)*EXP($Q$2*SQRT(G$6)*$D10) -> 9.4858849 | H10: =MAX(0,(G10-$H$7)) -> 3.7358849 | I10: =$H$2*EXP(-$Q$2*$Q$2/2*I$6)*EXP($Q$2*SQRT(I$6)*$D10) -> 9.7439434 | J10: =MAX(0,(I10-$J$7)) -> 3.9939434 | K10: =$H$2*EXP(-$Q$2*$Q$2/2*K$6)*EXP($Q$2*SQRT(K$6)*$D10) -> 9.9857286 | L10: =MAX(0,(K10-$L$7)) -> 4.2357286 | M10: =$H$2*EXP(-$Q$2*$Q$2/2*M$6)*EXP($Q$2*SQRT(M$6)*$D10) -> 10.192212 | N10: =MAX(0,(M10-$N$7)) -> 4.4422116 | O10: =$H$2*EXP(-$Q$2*$Q$2/2*O$6)*EXP($Q$2*SQRT(O$6)*$D10) -> 10.385852 | P10: =MAX(0,(O10-$P$7)) -> 4.6358525 | Q10: =$H$2*EXP(-$Q$2*$Q$2/2*Q$6)*EXP($Q$2*SQRT(Q$6)*$D10) -> 10.558942 | R10: =MAX((Q10-$R$7),0) -> 4.808942 | S10: =$H$2*EXP(-$Q$2*$Q$2/2*S$6)*EXP($Q$2*SQRT(S$6)*$D10) -> 10.726209 | T10: =MAX(0,(S10-$T$7)) -> 4.9762093 | U10: =$H$2*EXP(-$Q$2*$Q$2/2*U$6)*EXP($Q$2*SQRT(U$6)*$D10) -> 10.883907 | V10: =MAX(0,(U10-$V$7)) -> 5.133907 | W10: =$H$2*EXP(-$Q$2*$Q$2/2*W$6)*EXP($Q$2*SQRT(W$6)*$D10) -> 11.028923 | X10: =MAX(0,(W10-$X$7)) -> 5.2789235 | Y10: =$H$2*EXP(-$Q$2*$Q$2/2*Y$6)*EXP($Q$2*SQRT(Y$6)*$D10) -> 11.172098 | Z10: =MAX(0,(Y10-$Z$7)) -> 5.4220976 | AA10: =$H$2*EXP(-$Q$2*$Q$2/2*AA$6)*EXP($Q$2*SQRT(AA$6)*$D10) -> 11.305058 | AB10: =MAX(0,(AA10-$AB$7)) -> 5.5550576 | AC10: =$H$2*EXP(-$Q$2*$Q$2/2*AC$6)*EXP($Q$2*SQRT(AC$6)*$D10) -> 11.437383 | AD10: =MAX(0,(AC10-$AD$7)) -> 5.6873828 | AE10: =$H$2*EXP(-$Q$2*$Q$2/2*AE$6)*EXP($Q$2*SQRT(AE$6)*$D10) -> 11.565144 | AF10: =MAX((AE10-$AF$7),0) -> 5.8151441 | AG10: =$H$2*EXP(-$Q$2*$Q$2/2*AG$6)*EXP($Q$2*SQRT(AG$6)*$D10) -> 11.677025 | AH10: =MAX((AG10-$AH$7),0) -> 5.9270246 | AI10: =$H$2*EXP(-$Q$2*$Q$2/2*AI$6)*EXP($Q$2*SQRT(AI$6)*$D10) -> 11.797373 | AJ10: =MAX(0,(AI10-$AJ$7)) -> 6.0473735 | AK10: =$H$2*EXP(-$Q$2*$Q$2/2*AK$6)*EXP($Q$2*SQRT(AK$6)*$D10) -> 11.910633 | AL10: =MAX(0,(AK10-$AL$7)) -> 6.1606332 | AM10: =$H$2*EXP(-$Q$2*$Q$2/2*AM$6)*EXP($Q$2*SQRT(AM$6)*$D10) -> 12.024641 | AN10: =MAX(0,(AM10-$AN$7)) -> 6.2746411 | AO10: =$H$2*EXP(-$Q$2*$Q$2/2*AO$6)*EXP($Q$2*SQRT(AO$6)*$D10) -> 12.132278 | AP10: =MAX(0,(AO10-$AP$7)) -> 6.3822779 | AQ10: =$H$2*EXP(-$Q$2*$Q$2/2*AQ$6)*EXP($Q$2*SQRT(AQ$6)*$D10) -> 12.240934 | AR10: =MAX(0,(AQ10-$AR$7)) -> 6.4909335 | AS10: =$H$2*EXP(-$Q$2*$Q$2/2*AS$6)*EXP($Q$2*SQRT(AS$6)*$D10) -> 12.347168 | AT10: =MAX(0,(AS10-$AT$7)) -> 6.5971684
A11: 5.4716667 | B11: 4 | C11: =SQRT($E$2)*B11-INT(SQRT($E$2)*B11) -> 0.58300524 | D11: =_xlfn.NORM.S.INV(C11) -> 0.20958766 | E11: =$H$2*EXP(-$Q$2*$Q$2/2*E$6)*EXP($Q$2*SQRT(E$6)*$D11) -> 8.4830321 | F11: =MAX((E11-$F$7),0) -> 2.7330321 | G11: =$H$2*EXP(-$Q$2*$Q$2/2*G$6)*EXP($Q$2*SQRT(G$6)*$D11) -> 8.5164049 | H11: =MAX(0,(G11-$H$7)) -> 2.7664049 | I11: =$H$2*EXP(-$Q$2*$Q$2/2*I$6)*EXP($Q$2*SQRT(I$6)*$D11) -> 8.5352608 | J11: =MAX(0,(I11-$J$7)) -> 2.7852608 | K11: =$H$2*EXP(-$Q$2*$Q$2/2*K$6)*EXP($Q$2*SQRT(K$6)*$D11) -> 8.5500947 | L11: =MAX(0,(K11-$L$7)) -> 2.8000947 | M11: =$H$2*EXP(-$Q$2*$Q$2/2*M$6)*EXP($Q$2*SQRT(M$6)*$D11) -> 8.5606638 | N11: =MAX(0,(M11-$N$7)) -> 2.8106638 | O11: =$H$2*EXP(-$Q$2*$Q$2/2*O$6)*EXP($Q$2*SQRT(O$6)*$D11) -> 8.5688691 | P11: =MAX(0,(O11-$P$7)) -> 2.8188691 | Q11: =$H$2*EXP(-$Q$2*$Q$2/2*Q$6)*EXP($Q$2*SQRT(Q$6)*$D11) -> 8.5748404 | R11: =MAX((Q11-$R$7),0) -> 2.8248404 | S11: =$H$2*EXP(-$Q$2*$Q$2/2*S$6)*EXP($Q$2*SQRT(S$6)*$D11) -> 8.5794161 | T11: =MAX(0,(S11-$T$7)) -> 2.8294161 | U11: =$H$2*EXP(-$Q$2*$Q$2/2*U$6)*EXP($Q$2*SQRT(U$6)*$D11) -> 8.5826768 | V11: =MAX(0,(U11-$V$7)) -> 2.8326768 | W11: =$H$2*EXP(-$Q$2*$Q$2/2*W$6)*EXP($Q$2*SQRT(W$6)*$D11) -> 8.5847902 | X11: =MAX(0,(W11-$X$7)) -> 2.8347902 | Y11: =$H$2*EXP(-$Q$2*$Q$2/2*Y$6)*EXP($Q$2*SQRT(Y$6)*$D11) -> 8.5860596 | Z11: =MAX(0,(Y11-$Z$7)) -> 2.8360596 | AA11: =$H$2*EXP(-$Q$2*$Q$2/2*AA$6)*EXP($Q$2*SQRT(AA$6)*$D11) -> 8.5865232 | AB11: =MAX(0,(AA11-$AB$7)) -> 2.8365232 | AC11: =$H$2*EXP(-$Q$2*$Q$2/2*AC$6)*EXP($Q$2*SQRT(AC$6)*$D11) -> 8.5863114 | AD11: =MAX(0,(AC11-$AD$7)) -> 2.8363114 | AE11: =$H$2*EXP(-$Q$2*$Q$2/2*AE$6)*EXP($Q$2*SQRT(AE$6)*$D11) -> 8.5854789 | AF11: =MAX((AE11-$AF$7),0) -> 2.8354789 | AG11: =$H$2*EXP(-$Q$2*$Q$2/2*AG$6)*EXP($Q$2*SQRT(AG$6)*$D11) -> 8.5842502 | AH11: =MAX((AG11-$AH$7),0) -> 2.8342502 | AI11: =$H$2*EXP(-$Q$2*$Q$2/2*AI$6)*EXP($Q$2*SQRT(AI$6)*$D11) -> 8.5824143 | AJ11: =MAX(0,(AI11-$AJ$7)) -> 2.8324143 | AK11: =$H$2*EXP(-$Q$2*$Q$2/2*AK$6)*EXP($Q$2*SQRT(AK$6)*$D11) -> 8.5802057 | AL11: =MAX(0,(AK11-$AL$7)) -> 2.8302057 | AM11: =$H$2*EXP(-$Q$2*$Q$2/2*AM$6)*EXP($Q$2*SQRT(AM$6)*$D11) -> 8.5775172 | AN11: =MAX(0,(AM11-$AN$7)) -> 2.8275172 | AO11: =$H$2*EXP(-$Q$2*$Q$2/2*AO$6)*EXP($Q$2*SQRT(AO$6)*$D11) -> 8.5745554 | AP11: =MAX(0,(AO11-$AP$7)) -> 2.8245554 | AQ11: =$H$2*EXP(-$Q$2*$Q$2/2*AQ$6)*EXP($Q$2*SQRT(AQ$6)*$D11) -> 8.571153 | AR11: =MAX(0,(AQ11-$AR$7)) -> 2.821153 | AS11: =$H$2*EXP(-$Q$2*$Q$2/2*AS$6)*EXP($Q$2*SQRT(AS$6)*$D11) -> 8.5674298 | AT11: =MAX(0,(AS11-$AT$7)) -> 2.8174298
A12: 5.4383333 | B12: 5 | C12: =SQRT($E$2)*B12-INT(SQRT($E$2)*B12) -> 0.22875656 | D12: =_xlfn.NORM.S.INV(C12) -> -0.74294809 | E12: =$H$2*EXP(-$Q$2*$Q$2/2*E$6)*EXP($Q$2*SQRT(E$6)*$D12) -> 8.0588813 | F12: =MAX((E12-$F$7),0) -> 2.3088813 | G12: =$H$2*EXP(-$Q$2*$Q$2/2*G$6)*EXP($Q$2*SQRT(G$6)*$D12) -> 7.8801376 | H12: =MAX(0,(G12-$H$7)) -> 2.1301376 | I12: =$H$2*EXP(-$Q$2*$Q$2/2*I$6)*EXP($Q$2*SQRT(I$6)*$D12) -> 7.7587251 | J12: =MAX(0,(I12-$J$7)) -> 2.0087251 | K12: =$H$2*EXP(-$Q$2*$Q$2/2*K$6)*EXP($Q$2*SQRT(K$6)*$D12) -> 7.6457614 | L12: =MAX(0,(K12-$L$7)) -> 1.8957614 | M12: =$H$2*EXP(-$Q$2*$Q$2/2*M$6)*EXP($Q$2*SQRT(M$6)*$D12) -> 7.5499095 | N12: =MAX(0,(M12-$N$7)) -> 1.7999095 | O12: =$H$2*EXP(-$Q$2*$Q$2/2*O$6)*EXP($Q$2*SQRT(O$6)*$D12) -> 7.4605438 | P12: =MAX(0,(O12-$P$7)) -> 1.7105438 | Q12: =$H$2*EXP(-$Q$2*$Q$2/2*Q$6)*EXP($Q$2*SQRT(Q$6)*$D12) -> 7.3810966 | R12: =MAX((Q12-$R$7),0) -> 1.6310966 | S12: =$H$2*EXP(-$Q$2*$Q$2/2*S$6)*EXP($Q$2*SQRT(S$6)*$D12) -> 7.3047141 | T12: =MAX(0,(S12-$T$7)) -> 1.5547141 | U12: =$H$2*EXP(-$Q$2*$Q$2/2*U$6)*EXP($Q$2*SQRT(U$6)*$D12) -> 7.2330565 | V12: =MAX(0,(U12-$V$7)) -> 1.4830565 | W12: =$H$2*EXP(-$Q$2*$Q$2/2*W$6)*EXP($Q$2*SQRT(W$6)*$D12) -> 7.1674665 | X12: =MAX(0,(W12-$X$7)) -> 1.4174665 | Y12: =$H$2*EXP(-$Q$2*$Q$2/2*Y$6)*EXP($Q$2*SQRT(Y$6)*$D12) -> 7.1029975 | Z12: =MAX(0,(Y12-$Z$7)) -> 1.3529975 | AA12: =$H$2*EXP(-$Q$2*$Q$2/2*AA$6)*EXP($Q$2*SQRT(AA$6)*$D12) -> 7.0433844 | AB12: =MAX(0,(AA12-$AB$7)) -> 1.2933844 | AC12: =$H$2*EXP(-$Q$2*$Q$2/2*AC$6)*EXP($Q$2*SQRT(AC$6)*$D12) -> 6.9843016 | AD12: =MAX(0,(AC12-$AD$7)) -> 1.2343016 | AE12: =$H$2*EXP(-$Q$2*$Q$2/2*AE$6)*EXP($Q$2*SQRT(AE$6)*$D12) -> 6.9274892 | AF12: =MAX((AE12-$AF$7),0) -> 1.1774892 | AG12: =$H$2*EXP(-$Q$2*$Q$2/2*AG$6)*EXP($Q$2*SQRT(AG$6)*$D12) -> 6.8779264 | AH12: =MAX((AG12-$AH$7),0) -> 1.1279264 | AI12: =$H$2*EXP(-$Q$2*$Q$2/2*AI$6)*EXP($Q$2*SQRT(AI$6)*$D12) -> 6.8248078 | AJ12: =MAX(0,(AI12-$AJ$7)) -> 1.0748078 | AK12: =$H$2*EXP(-$Q$2*$Q$2/2*AK$6)*EXP($Q$2*SQRT(AK$6)*$D12) -> 6.7750033 | AL12: =MAX(0,(AK12-$AL$7)) -> 1.0250033 | AM12: =$H$2*EXP(-$Q$2*$Q$2/2*AM$6)*EXP($Q$2*SQRT(AM$6)*$D12) -> 6.725051 | AN12: =MAX(0,(AM12-$AN$7)) -> 0.97505095 | AO12: =$H$2*EXP(-$Q$2*$Q$2/2*AO$6)*EXP($Q$2*SQRT(AO$6)*$D12) -> 6.6780567 | AP12: =MAX(0,(AO12-$AP$7)) -> 0.92805665 | AQ12: =$H$2*EXP(-$Q$2*$Q$2/2*AQ$6)*EXP($Q$2*SQRT(AQ$6)*$D12) -> 6.6307813 | AR12: =MAX(0,(AQ12-$AR$7)) -> 0.88078135 | AS12: =$H$2*EXP(-$Q$2*$Q$2/2*AS$6)*EXP($Q$2*SQRT(AS$6)*$D12) -> 6.5847182 | AT12: =MAX(0,(AS12-$AT$7)) -> 0.83471823
A13: 5.4066667 | B13: 6 | C13: =SQRT($E$2)*B13-INT(SQRT($E$2)*B13) -> 0.87450787 | D13: =_xlfn.NORM.S.INV(C13) -> 1.147962 | E13: =$H$2*EXP(-$Q$2*$Q$2/2*E$6)*EXP($Q$2*SQRT(E$6)*$D13) -> 8.9226998 | F13: =MAX((E13-$F$7),0) -> 3.1726998 | G13: =$H$2*EXP(-$Q$2*$Q$2/2*G$6)*EXP($Q$2*SQRT(G$6)*$D13) -> 9.1934274 | H13: =MAX(0,(G13-$H$7)) -> 3.4434274 | I13: =$H$2*EXP(-$Q$2*$Q$2/2*I$6)*EXP($Q$2*SQRT(I$6)*$D13) -> 9.3762102 | J13: =MAX(0,(I13-$J$7)) -> 3.6262102 | K13: =$H$2*EXP(-$Q$2*$Q$2/2*K$6)*EXP($Q$2*SQRT(K$6)*$D13) -> 9.5455138 | L13: =MAX(0,(K13-$L$7)) -> 3.7955138 | M13: =$H$2*EXP(-$Q$2*$Q$2/2*M$6)*EXP($Q$2*SQRT(M$6)*$D13) -> 9.6886196 | N13: =MAX(0,(M13-$N$7)) -> 3.9386196 | O13: =$H$2*EXP(-$Q$2*$Q$2/2*O$6)*EXP($Q$2*SQRT(O$6)*$D13) -> 9.8215998 | P13: =MAX(0,(O13-$P$7)) -> 4.0715998 | Q13: =$H$2*EXP(-$Q$2*$Q$2/2*Q$6)*EXP($Q$2*SQRT(Q$6)*$D13) -> 9.9394712 | R13: =MAX((Q13-$R$7),0) -> 4.1894712 | S13: =$H$2*EXP(-$Q$2*$Q$2/2*S$6)*EXP($Q$2*SQRT(S$6)*$D13) -> 10.052491 | T13: =MAX(0,(S13-$T$7)) -> 4.3024914 | U13: =$H$2*EXP(-$Q$2*$Q$2/2*U$6)*EXP($Q$2*SQRT(U$6)*$D13) -> 10.158253 | V13: =MAX(0,(U13-$V$7)) -> 4.4082529 | W13: =$H$2*EXP(-$Q$2*$Q$2/2*W$6)*EXP($Q$2*SQRT(W$6)*$D13) -> 10.254834 | X13: =MAX(0,(W13-$X$7)) -> 4.5048345 | Y13: =$H$2*EXP(-$Q$2*$Q$2/2*Y$6)*EXP($Q$2*SQRT(Y$6)*$D13) -> 10.349558 | Z13: =MAX(0,(Y13-$Z$7)) -> 4.5995577 | AA13: =$H$2*EXP(-$Q$2*$Q$2/2*AA$6)*EXP($Q$2*SQRT(AA$6)*$D13) -> 10.436964 | AB13: =MAX(0,(AA13-$AB$7)) -> 4.6869642 | AC13: =$H$2*EXP(-$Q$2*$Q$2/2*AC$6)*EXP($Q$2*SQRT(AC$6)*$D13) -> 10.523421 | AD13: =MAX(0,(AC13-$AD$7)) -> 4.773421 | AE13: =$H$2*EXP(-$Q$2*$Q$2/2*AE$6)*EXP($Q$2*SQRT(AE$6)*$D13) -> 10.606394 | AF13: =MAX((AE13-$AF$7),0) -> 4.8563938 | AG13: =$H$2*EXP(-$Q$2*$Q$2/2*AG$6)*EXP($Q$2*SQRT(AG$6)*$D13) -> 10.678649 | AH13: =MAX((AG13-$AH$7),0) -> 4.9286494 | AI13: =$H$2*EXP(-$Q$2*$Q$2/2*AI$6)*EXP($Q$2*SQRT(AI$6)*$D13) -> 10.755955 | AJ13: =MAX(0,(AI13-$AJ$7)) -> 5.0059547 | AK13: =$H$2*EXP(-$Q$2*$Q$2/2*AK$6)*EXP($Q$2*SQRT(AK$6)*$D13) -> 10.82831 | AL13: =MAX(0,(AK13-$AL$7)) -> 5.0783103 | AM13: =$H$2*EXP(-$Q$2*$Q$2/2*AM$6)*EXP($Q$2*SQRT(AM$6)*$D13) -> 10.900757 | AN13: =MAX(0,(AM13-$AN$7)) -> 5.1507572 | AO13: =$H$2*EXP(-$Q$2*$Q$2/2*AO$6)*EXP($Q$2*SQRT(AO$6)*$D13) -> 10.9688 | AP13: =MAX(0,(AO13-$AP$7)) -> 5.2188003 | AQ13: =$H$2*EXP(-$Q$2*$Q$2/2*AQ$6)*EXP($Q$2*SQRT(AQ$6)*$D13) -> 11.037138 | AR13: =MAX(0,(AQ13-$AR$7)) -> 5.2871383 | AS13: =$H$2*EXP(-$Q$2*$Q$2/2*AS$6)*EXP($Q$2*SQRT(AS$6)*$D13) -> 11.103615 | AT13: =MAX(0,(AS13-$AT$7)) -> 5.3536154
A14: 5.3833333 | B14: 7 | C14: =SQRT($E$2)*B14-INT(SQRT($E$2)*B14) -> 0.52025918 | D14: =_xlfn.NORM.S.INV(C14) -> 0.050804073 | E14: =$H$2*EXP(-$Q$2*$Q$2/2*E$6)*EXP($Q$2*SQRT(E$6)*$D14) -> 8.4108084 | F14: =MAX((E14-$F$7),0) -> 2.6608084 | G14: =$H$2*EXP(-$Q$2*$Q$2/2*G$6)*EXP($Q$2*SQRT(G$6)*$D14) -> 8.4068812 | H14: =MAX(0,(G14-$H$7)) -> 2.6568812 | I14: =$H$2*EXP(-$Q$2*$Q$2/2*I$6)*EXP($Q$2*SQRT(I$6)*$D14) -> 8.4006171 | J14: =MAX(0,(I14-$J$7)) -> 2.6506171 | K14: =$H$2*EXP(-$Q$2*$Q$2/2*K$6)*EXP($Q$2*SQRT(K$6)*$D14) -> 8.3922385 | L14: =MAX(0,(K14-$L$7)) -> 2.6422385 | M14: =$H$2*EXP(-$Q$2*$Q$2/2*M$6)*EXP($Q$2*SQRT(M$6)*$D14) -> 8.3832337 | N14: =MAX(0,(M14-$N$7)) -> 2.6332337 | O14: =$H$2*EXP(-$Q$2*$Q$2/2*O$6)*EXP($Q$2*SQRT(O$6)*$D14) -> 8.3732924 | P14: =MAX(0,(O14-$P$7)) -> 2.6232924 | Q14: =$H$2*EXP(-$Q$2*$Q$2/2*Q$6)*EXP($Q$2*SQRT(Q$6)*$D14) -> 8.3632157 | R14: =MAX((Q14-$R$7),0) -> 2.6132157 | S14: =$H$2*EXP(-$Q$2*$Q$2/2*S$6)*EXP($Q$2*SQRT(S$6)*$D14) -> 8.3524385 | T14: =MAX(0,(S14-$T$7)) -> 2.6024385 | U14: =$H$2*EXP(-$Q$2*$Q$2/2*U$6)*EXP($Q$2*SQRT(U$6)*$D14) -> 8.3413649 | V14: =MAX(0,(U14-$V$7)) -> 2.5913649 | W14: =$H$2*EXP(-$Q$2*$Q$2/2*W$6)*EXP($Q$2*SQRT(W$6)*$D14) -> 8.330417 | X14: =MAX(0,(W14-$X$7)) -> 2.580417 | Y14: =$H$2*EXP(-$Q$2*$Q$2/2*Y$6)*EXP($Q$2*SQRT(Y$6)*$D14) -> 8.3189045 | Z14: =MAX(0,(Y14-$Z$7)) -> 2.5689045 | AA14: =$H$2*EXP(-$Q$2*$Q$2/2*AA$6)*EXP($Q$2*SQRT(AA$6)*$D14) -> 8.307599 | AB14: =MAX(0,(AA14-$AB$7)) -> 2.557599 | AC14: =$H$2*EXP(-$Q$2*$Q$2/2*AC$6)*EXP($Q$2*SQRT(AC$6)*$D14) -> 8.295771 | AD14: =MAX(0,(AC14-$AD$7)) -> 2.545771 | AE14: =$H$2*EXP(-$Q$2*$Q$2/2*AE$6)*EXP($Q$2*SQRT(AE$6)*$D14) -> 8.2838148 | AF14: =MAX((AE14-$AF$7),0) -> 2.5338148 | AG14: =$H$2*EXP(-$Q$2*$Q$2/2*AG$6)*EXP($Q$2*SQRT(AG$6)*$D14) -> 8.272919 | AH14: =MAX((AG14-$AH$7),0) -> 2.522919 | AI14: =$H$2*EXP(-$Q$2*$Q$2/2*AI$6)*EXP($Q$2*SQRT(AI$6)*$D14) -> 8.2607615 | AJ14: =MAX(0,(AI14-$AJ$7)) -> 2.5107615 | AK14: =$H$2*EXP(-$Q$2*$Q$2/2*AK$6)*EXP($Q$2*SQRT(AK$6)*$D14) -> 8.2489124 | AL14: =MAX(0,(AK14-$AL$7)) -> 2.4989124 | AM14: =$H$2*EXP(-$Q$2*$Q$2/2*AM$6)*EXP($Q$2*SQRT(AM$6)*$D14) -> 8.2365915 | AN14: =MAX(0,(AM14-$AN$7)) -> 2.4865915 | AO14: =$H$2*EXP(-$Q$2*$Q$2/2*AO$6)*EXP($Q$2*SQRT(AO$6)*$D14) -> 8.2246017 | AP14: =MAX(0,(AO14-$AP$7)) -> 2.4746017 | AQ14: =$H$2*EXP(-$Q$2*$Q$2/2*AQ$6)*EXP($Q$2*SQRT(AQ$6)*$D14) -> 8.212151 | AR14: =MAX(0,(AQ14-$AR$7)) -> 2.462151 | AS14: =$H$2*EXP(-$Q$2*$Q$2/2*AS$6)*EXP($Q$2*SQRT(AS$6)*$D14) -> 8.1996443 | AT14: =MAX(0,(AS14-$AT$7)) -> 2.4496443
A15: 5.3616667 | B15: 8 | C15: =SQRT($E$2)*B15-INT(SQRT($E$2)*B15) -> 0.16601049 | D15: =_xlfn.NORM.S.INV(C15) -> -0.97005119 | E15: =$H$2*EXP(-$Q$2*$Q$2/2*E$6)*EXP($Q$2*SQRT(E$6)*$D15) -> 7.960927 | F15: =MAX((E15-$F$7),0) -> 2.210927 | G15: =$H$2*EXP(-$Q$2*$Q$2/2*G$6)*EXP($Q$2*SQRT(G$6)*$D15) -> 7.7355945 | H15: =MAX(0,(G15-$H$7)) -> 1.9855945 | I15: =$H$2*EXP(-$Q$2*$Q$2/2*I$6)*EXP($Q$2*SQRT(I$6)*$D15) -> 7.584265 | J15: =MAX(0,(I15-$J$7)) -> 1.834265 | K15: =$H$2*EXP(-$Q$2*$Q$2/2*K$6)*EXP($Q$2*SQRT(K$6)*$D15) -> 7.4446696 | L15: =MAX(0,(K15-$L$7)) -> 1.6946696 | M15: =$H$2*EXP(-$Q$2*$Q$2/2*M$6)*EXP($Q$2*SQRT(M$6)*$D15) -> 7.3271017 | N15: =MAX(0,(M15-$N$7)) -> 1.5771017 | O15: =$H$2*EXP(-$Q$2*$Q$2/2*O$6)*EXP($Q$2*SQRT(O$6)*$D15) -> 7.2181986 | P15: =MAX(0,(O15-$P$7)) -> 1.4681986 | Q15: =$H$2*EXP(-$Q$2*$Q$2/2*Q$6)*EXP($Q$2*SQRT(Q$6)*$D15) -> 7.1219439 | R15: =MAX((Q15-$R$7),0) -> 1.3719439 | S15: =$H$2*EXP(-$Q$2*$Q$2/2*S$6)*EXP($Q$2*SQRT(S$6)*$D15) -> 7.0298902 | T15: =MAX(0,(S15-$T$7)) -> 1.2798902 | U15: =$H$2*EXP(-$Q$2*$Q$2/2*U$6)*EXP($Q$2*SQRT(U$6)*$D15) -> 6.9439578 | V15: =MAX(0,(U15-$V$7)) -> 1.1939578 | W15: =$H$2*EXP(-$Q$2*$Q$2/2*W$6)*EXP($Q$2*SQRT(W$6)*$D15) -> 6.8656579 | X15: =MAX(0,(W15-$X$7)) -> 1.1156579 | Y15: =$H$2*EXP(-$Q$2*$Q$2/2*Y$6)*EXP($Q$2*SQRT(Y$6)*$D15) -> 6.7890231 | Z15: =MAX(0,(Y15-$Z$7)) -> 1.0390231 | AA15: =$H$2*EXP(-$Q$2*$Q$2/2*AA$6)*EXP($Q$2*SQRT(AA$6)*$D15) -> 6.7184447 | AB15: =MAX(0,(AA15-$AB$7)) -> 0.96844467 | AC15: =$H$2*EXP(-$Q$2*$Q$2/2*AC$6)*EXP($Q$2*SQRT(AC$6)*$D15) -> 6.64876 | AD15: =MAX(0,(AC15-$AD$7)) -> 0.89875999 | AE15: =$H$2*EXP(-$Q$2*$Q$2/2*AE$6)*EXP($Q$2*SQRT(AE$6)*$D15) -> 6.5819998 | AF15: =MAX((AE15-$AF$7),0) -> 0.83199977 | AG15: =$H$2*EXP(-$Q$2*$Q$2/2*AG$6)*EXP($Q$2*SQRT(AG$6)*$D15) -> 6.5239538 | AH15: =MAX((AG15-$AH$7),0) -> 0.77395383 | AI15: =$H$2*EXP(-$Q$2*$Q$2/2*AI$6)*EXP($Q$2*SQRT(AI$6)*$D15) -> 6.4619433 | AJ15: =MAX(0,(AI15-$AJ$7)) -> 0.71194333 | AK15: =$H$2*EXP(-$Q$2*$Q$2/2*AK$6)*EXP($Q$2*SQRT(AK$6)*$D15) -> 6.4039877 | AL15: =MAX(0,(AK15-$AL$7)) -> 0.65398768 | AM15: =$H$2*EXP(-$Q$2*$Q$2/2*AM$6)*EXP($Q$2*SQRT(AM$6)*$D15) -> 6.346039 | AN15: =MAX(0,(AM15-$AN$7)) -> 0.59603904 | AO15: =$H$2*EXP(-$Q$2*$Q$2/2*AO$6)*EXP($Q$2*SQRT(AO$6)*$D15) -> 6.2916842 | AP15: =MAX(0,(AO15-$AP$7)) -> 0.54168421 | AQ15: =$H$2*EXP(-$Q$2*$Q$2/2*AQ$6)*EXP($Q$2*SQRT(AQ$6)*$D15) -> 6.2371617 | AR15: =MAX(0,(AQ15-$AR$7)) -> 0.48716168 | AS15: =$H$2*EXP(-$Q$2*$Q$2/2*AS$6)*EXP($Q$2*SQRT(AS$6)*$D15) -> 6.1841877 | AT15: =MAX(0,(AS15-$AT$7)) -> 0.43418767
A16: 5.3383333 | B16: 9 | C16: =SQRT($E$2)*B16-INT(SQRT($E$2)*B16) -> 0.8117618 | D16: =_xlfn.NORM.S.INV(C16) -> 0.88440727 | E16: =$H$2*EXP(-$Q$2*$Q$2/2*E$6)*EXP($Q$2*SQRT(E$6)*$D16) -> 8.7969615 | F16: =MAX((E16-$F$7),0) -> 3.0469615 | G16: =$H$2*EXP(-$Q$2*$Q$2/2*G$6)*EXP($Q$2*SQRT(G$6)*$D16) -> 8.998018 | H16: =MAX(0,(G16-$H$7)) -> 3.248018 | I16: =$H$2*EXP(-$Q$2*$Q$2/2*I$6)*EXP($Q$2*SQRT(I$6)*$D16) -> 9.1319844 | J16: =MAX(0,(I16-$J$7)) -> 3.3819844 | K16: =$H$2*EXP(-$Q$2*$Q$2/2*K$6)*EXP($Q$2*SQRT(K$6)*$D16) -> 9.2547796 | L16: =MAX(0,(K16-$L$7)) -> 3.5047796 | M16: =$H$2*EXP(-$Q$2*$Q$2/2*M$6)*EXP($Q$2*SQRT(M$6)*$D16) -> 9.3575953 | N16: =MAX(0,(M16-$N$7)) -> 3.6075953 | O16: =$H$2*EXP(-$Q$2*$Q$2/2*O$6)*EXP($Q$2*SQRT(O$6)*$D16) -> 9.452325 | P16: =MAX(0,(O16-$P$7)) -> 3.702325 | Q16: =$H$2*EXP(-$Q$2*$Q$2/2*Q$6)*EXP($Q$2*SQRT(Q$6)*$D16) -> 9.5356324 | R16: =MAX((Q16-$R$7),0) -> 3.7856324 | S16: =$H$2*EXP(-$Q$2*$Q$2/2*S$6)*EXP($Q$2*SQRT(S$6)*$D16) -> 9.6149237 | T16: =MAX(0,(S16-$T$7)) -> 3.8649237 | U16: =$H$2*EXP(-$Q$2*$Q$2/2*U$6)*EXP($Q$2*SQRT(U$6)*$D16) -> 9.688597 | V16: =MAX(0,(U16-$V$7)) -> 3.938597 | W16: =$H$2*EXP(-$Q$2*$Q$2/2*W$6)*EXP($Q$2*SQRT(W$6)*$D16) -> 9.7554277 | X16: =MAX(0,(W16-$X$7)) -> 4.0054277 | Y16: =$H$2*EXP(-$Q$2*$Q$2/2*Y$6)*EXP($Q$2*SQRT(Y$6)*$D16) -> 9.8205534 | Z16: =MAX(0,(Y16-$Z$7)) -> 4.0705534 | AA16: =$H$2*EXP(-$Q$2*$Q$2/2*AA$6)*EXP($Q$2*SQRT(AA$6)*$D16) -> 9.8802771 | AB16: =MAX(0,(AA16-$AB$7)) -> 4.1302771 | AC16: =$H$2*EXP(-$Q$2*$Q$2/2*AC$6)*EXP($Q$2*SQRT(AC$6)*$D16) -> 9.938998 | AD16: =MAX(0,(AC16-$AD$7)) -> 4.188998 | AE16: =$H$2*EXP(-$Q$2*$Q$2/2*AE$6)*EXP($Q$2*SQRT(AE$6)*$D16) -> 9.9950188 | AF16: =MAX((AE16-$AF$7),0) -> 4.2450188 | AG16: =$H$2*EXP(-$Q$2*$Q$2/2*AG$6)*EXP($Q$2*SQRT(AG$6)*$D16) -> 10.043535 | AH16: =MAX((AG16-$AH$7),0) -> 4.2935348 | AI16: =$H$2*EXP(-$Q$2*$Q$2/2*AI$6)*EXP($Q$2*SQRT(AI$6)*$D16) -> 10.095162 | AJ16: =MAX(0,(AI16-$AJ$7)) -> 4.345162 | AK16: =$H$2*EXP(-$Q$2*$Q$2/2*AK$6)*EXP($Q$2*SQRT(AK$6)*$D16) -> 10.14322 | AL16: =MAX(0,(AK16-$AL$7)) -> 4.3932196 | AM16: =$H$2*EXP(-$Q$2*$Q$2/2*AM$6)*EXP($Q$2*SQRT(AM$6)*$D16) -> 10.19108 | AN16: =MAX(0,(AM16-$AN$7)) -> 4.4410798 | AO16: =$H$2*EXP(-$Q$2*$Q$2/2*AO$6)*EXP($Q$2*SQRT(AO$6)*$D16) -> 10.235794 | AP16: =MAX(0,(AO16-$AP$7)) -> 4.4857936 | AQ16: =$H$2*EXP(-$Q$2*$Q$2/2*AQ$6)*EXP($Q$2*SQRT(AQ$6)*$D16) -> 10.280468 | AR16: =MAX(0,(AQ16-$AR$7)) -> 4.5304678 | AS16: =$H$2*EXP(-$Q$2*$Q$2/2*AS$6)*EXP($Q$2*SQRT(AS$6)*$D16) -> 10.323699 | AT16: =MAX(0,(AS16-$AT$7)) -> 4.5736991
A17: 5.3141667 | B17: 10 | C17: =SQRT($E$2)*B17-INT(SQRT($E$2)*B17) -> 0.45751311 | D17: =_xlfn.NORM.S.INV(C17) -> -0.10670096 | E17: =$H$2*EXP(-$Q$2*$Q$2/2*E$6)*EXP($Q$2*SQRT(E$6)*$D17) -> 8.3397738 | F17: =MAX((E17-$F$7),0) -> 2.5897738 | G17: =$H$2*EXP(-$Q$2*$Q$2/2*G$6)*EXP($Q$2*SQRT(G$6)*$D17) -> 8.2996309 | H17: =MAX(0,(G17-$H$7)) -> 2.5496309 | I17: =$H$2*EXP(-$Q$2*$Q$2/2*I$6)*EXP($Q$2*SQRT(I$6)*$D17) -> 8.2691561 | J17: =MAX(0,(I17-$J$7)) -> 2.5191561 | K17: =$H$2*EXP(-$Q$2*$Q$2/2*K$6)*EXP($Q$2*SQRT(K$6)*$D17) -> 8.2385329 | L17: =MAX(0,(K17-$L$7)) -> 2.4885329 | M17: =$H$2*EXP(-$Q$2*$Q$2/2*M$6)*EXP($Q$2*SQRT(M$6)*$D17) -> 8.2108658 | N17: =MAX(0,(M17-$N$7)) -> 2.4608658 | O17: =$H$2*EXP(-$Q$2*$Q$2/2*O$6)*EXP($Q$2*SQRT(O$6)*$D17) -> 8.1837009 | P17: =MAX(0,(O17-$P$7)) -> 2.4337009 | Q17: =$H$2*EXP(-$Q$2*$Q$2/2*Q$6)*EXP($Q$2*SQRT(Q$6)*$D17) -> 8.1584553 | R17: =MAX((Q17-$R$7),0) -> 2.4084553 | S17: =$H$2*EXP(-$Q$2*$Q$2/2*S$6)*EXP($Q$2*SQRT(S$6)*$D17) -> 8.1332216 | T17: =MAX(0,(S17-$T$7)) -> 2.3832216 | U17: =$H$2*EXP(-$Q$2*$Q$2/2*U$6)*EXP($Q$2*SQRT(U$6)*$D17) -> 8.1086996 | V17: =MAX(0,(U17-$V$7)) -> 2.3586996 | W17: =$H$2*EXP(-$Q$2*$Q$2/2*W$6)*EXP($Q$2*SQRT(W$6)*$D17) -> 8.0855392 | X17: =MAX(0,(W17-$X$7)) -> 2.3355392 | Y17: =$H$2*EXP(-$Q$2*$Q$2/2*Y$6)*EXP($Q$2*SQRT(Y$6)*$D17) -> 8.0621136 | Z17: =MAX(0,(Y17-$Z$7)) -> 2.3121136 | AA17: =$H$2*EXP(-$Q$2*$Q$2/2*AA$6)*EXP($Q$2*SQRT(AA$6)*$D17) -> 8.039873 | AB17: =MAX(0,(AA17-$AB$7)) -> 2.289873 | AC17: =$H$2*EXP(-$Q$2*$Q$2/2*AC$6)*EXP($Q$2*SQRT(AC$6)*$D17) -> 8.0172839 | AD17: =MAX(0,(AC17-$AD$7)) -> 2.2672839 | AE17: =$H$2*EXP(-$Q$2*$Q$2/2*AE$6)*EXP($Q$2*SQRT(AE$6)*$D17) -> 7.9950524 | AF17: =MAX((AE17-$AF$7),0) -> 2.2450524 | AG17: =$H$2*EXP(-$Q$2*$Q$2/2*AG$6)*EXP($Q$2*SQRT(AG$6)*$D17) -> 7.9752509 | AH17: =MAX((AG17-$AH$7),0) -> 2.2252509 | AI17: =$H$2*EXP(-$Q$2*$Q$2/2*AI$6)*EXP($Q$2*SQRT(AI$6)*$D17) -> 7.9536095 | AJ17: =MAX(0,(AI17-$AJ$7)) -> 2.2036095 | AK17: =$H$2*EXP(-$Q$2*$Q$2/2*AK$6)*EXP($Q$2*SQRT(AK$6)*$D17) -> 7.9329257 | AL17: =MAX(0,(AK17-$AL$7)) -> 2.1829257 | AM17: =$H$2*EXP(-$Q$2*$Q$2/2*AM$6)*EXP($Q$2*SQRT(AM$6)*$D17) -> 7.9117999 | AN17: =MAX(0,(AM17-$AN$7)) -> 2.1617999 | AO17: =$H$2*EXP(-$Q$2*$Q$2/2*AO$6)*EXP($Q$2*SQRT(AO$6)*$D17) -> 7.8915781 | AP17: =MAX(0,(AO17-$AP$7)) -> 2.1415781 | AQ17: =$H$2*EXP(-$Q$2*$Q$2/2*AQ$6)*EXP($Q$2*SQRT(AQ$6)*$D17) -> 7.870897 | AR17: =MAX(0,(AQ17-$AR$7)) -> 2.120897 | AS17: =$H$2*EXP(-$Q$2*$Q$2/2*AS$6)*EXP($Q$2*SQRT(AS$6)*$D17) -> 7.8504203 | AT17: =MAX(0,(AS17-$AT$7)) -> 2.1004203
A18: 5.29 | B18: 11 | C18: =SQRT($E$2)*B18-INT(SQRT($E$2)*B18) -> 0.10326442 | D18: =_xlfn.NORM.S.INV(C18) -> -1.2631679 | E18: =$H$2*EXP(-$Q$2*$Q$2/2*E$6)*EXP($Q$2*SQRT(E$6)*$D18) -> 7.8362577 | F18: =MAX((E18-$F$7),0) -> 2.0862577 | G18: =$H$2*EXP(-$Q$2*$Q$2/2*G$6)*EXP($Q$2*SQRT(G$6)*$D18) -> 7.5529485 | H18: =MAX(0,(G18-$H$7)) -> 1.8029485 | I18: =$H$2*EXP(-$Q$2*$Q$2/2*I$6)*EXP($Q$2*SQRT(I$6)*$D18) -> 7.3648796 | J18: =MAX(0,(I18-$J$7)) -> 1.6148796 | K18: =$H$2*EXP(-$Q$2*$Q$2/2*K$6)*EXP($Q$2*SQRT(K$6)*$D18) -> 7.1929235 | L18: =MAX(0,(K18-$L$7)) -> 1.4429235 | M18: =$H$2*EXP(-$Q$2*$Q$2/2*M$6)*EXP($Q$2*SQRT(M$6)*$D18) -> 7.049221 | N18: =MAX(0,(M18-$N$7)) -> 1.299221 | O18: =$H$2*EXP(-$Q$2*$Q$2/2*O$6)*EXP($Q$2*SQRT(O$6)*$D18) -> 6.9170097 | P18: =MAX(0,(O18-$P$7)) -> 1.1670097 | Q18: =$H$2*EXP(-$Q$2*$Q$2/2*Q$6)*EXP($Q$2*SQRT(Q$6)*$D18) -> 6.8008661 | R18: =MAX((Q18-$R$7),0) -> 1.0508661 | S18: =$H$2*EXP(-$Q$2*$Q$2/2*S$6)*EXP($Q$2*SQRT(S$6)*$D18) -> 6.6904101 | T18: =MAX(0,(S18-$T$7)) -> 0.94041005 | U18: =$H$2*EXP(-$Q$2*$Q$2/2*U$6)*EXP($Q$2*SQRT(U$6)*$D18) -> 6.5878395 | V18: =MAX(0,(U18-$V$7)) -> 0.83783948 | W18: =$H$2*EXP(-$Q$2*$Q$2/2*W$6)*EXP($Q$2*SQRT(W$6)*$D18) -> 6.49483 | X18: =MAX(0,(W18-$X$7)) -> 0.74482997 | Y18: =$H$2*EXP(-$Q$2*$Q$2/2*Y$6)*EXP($Q$2*SQRT(Y$6)*$D18) -> 6.4042112 | Z18: =MAX(0,(Y18-$Z$7)) -> 0.65421123 | AA18: =$H$2*EXP(-$Q$2*$Q$2/2*AA$6)*EXP($Q$2*SQRT(AA$6)*$D18) -> 6.3211128 | AB18: =MAX(0,(AA18-$AB$7)) -> 0.57111284 | AC18: =$H$2*EXP(-$Q$2*$Q$2/2*AC$6)*EXP($Q$2*SQRT(AC$6)*$D18) -> 6.2394021 | AD18: =MAX(0,(AC18-$AD$7)) -> 0.48940212 | AE18: =$H$2*EXP(-$Q$2*$Q$2/2*AE$6)*EXP($Q$2*SQRT(AE$6)*$D18) -> 6.1614313 | AF18: =MAX((AE18-$AF$7),0) -> 0.41143129 | AG18: =$H$2*EXP(-$Q$2*$Q$2/2*AG$6)*EXP($Q$2*SQRT(AG$6)*$D18) -> 6.0938838 | AH18: =MAX((AG18-$AH$7),0) -> 0.34388384 | AI18: =$H$2*EXP(-$Q$2*$Q$2/2*AI$6)*EXP($Q$2*SQRT(AI$6)*$D18) -> 6.0219742 | AJ18: =MAX(0,(AI18-$AJ$7)) -> 0.27197421 | AK18: =$H$2*EXP(-$Q$2*$Q$2/2*AK$6)*EXP($Q$2*SQRT(AK$6)*$D18) -> 5.9550003 | AL18: =MAX(0,(AK18-$AL$7)) -> 0.20500034 | AM18: =$H$2*EXP(-$Q$2*$Q$2/2*AM$6)*EXP($Q$2*SQRT(AM$6)*$D18) -> 5.8882593 | AN18: =MAX(0,(AM18-$AN$7)) -> 0.13825927 | AO18: =$H$2*EXP(-$Q$2*$Q$2/2*AO$6)*EXP($Q$2*SQRT(AO$6)*$D18) -> 5.8258607 | AP18: =MAX(0,(AO18-$AP$7)) -> 0.075860653 | AQ18: =$H$2*EXP(-$Q$2*$Q$2/2*AQ$6)*EXP($Q$2*SQRT(AQ$6)*$D18) -> 5.7634665 | AR18: =MAX(0,(AQ18-$AR$7)) -> 0.013466504 | AS18: =$H$2*EXP(-$Q$2*$Q$2/2*AS$6)*EXP($Q$2*SQRT(AS$6)*$D18) -> 5.7030327 | AT18: =MAX(0,(AS18-$AT$7)) -> 0
A19: 5.2541667 | B19: 12 | C19: =SQRT($E$2)*B19-INT(SQRT($E$2)*B19) -> 0.74901573 | D19: =_xlfn.NORM.S.INV(C19) -> 0.67139562 | E19: =$H$2*EXP(-$Q$2*$Q$2/2*E$6)*EXP($Q$2*SQRT(E$6)*$D19) -> 8.6966326 | F19: =MAX((E19-$F$7),0) -> 2.9466326 | G19: =$H$2*EXP(-$Q$2*$Q$2/2*G$6)*EXP($Q$2*SQRT(G$6)*$D19) -> 8.8431223 | H19: =MAX(0,(G19-$H$7)) -> 3.0931223 | I19: =$H$2*EXP(-$Q$2*$Q$2/2*I$6)*EXP($Q$2*SQRT(I$6)*$D19) -> 8.9392512 | J19: =MAX(0,(I19-$J$7)) -> 3.1892512 | K19: =$H$2*EXP(-$Q$2*$Q$2/2*K$6)*EXP($Q$2*SQRT(K$6)*$D19) -> 9.0262842 | L19: =MAX(0,(K19-$L$7)) -> 3.2762842 | M19: =$H$2*EXP(-$Q$2*$Q$2/2*M$6)*EXP($Q$2*SQRT(M$6)*$D19) -> 9.0983357 | N19: =MAX(0,(M19-$N$7)) -> 3.3483357 | O19: =$H$2*EXP(-$Q$2*$Q$2/2*O$6)*EXP($Q$2*SQRT(O$6)*$D19) -> 9.1640378 | P19: =MAX(0,(O19-$P$7)) -> 3.4140378 | Q19: =$H$2*EXP(-$Q$2*$Q$2/2*Q$6)*EXP($Q$2*SQRT(Q$6)*$D19) -> 9.2212607 | R19: =MAX((Q19-$R$7),0) -> 3.4712607 | S19: =$H$2*EXP(-$Q$2*$Q$2/2*S$6)*EXP($Q$2*SQRT(S$6)*$D19) -> 9.2752274 | T19: =MAX(0,(S19-$T$7)) -> 3.5252274 | U19: =$H$2*EXP(-$Q$2*$Q$2/2*U$6)*EXP($Q$2*SQRT(U$6)*$D19) -> 9.3249237 | V19: =MAX(0,(U19-$V$7)) -> 3.5749237 | W19: =$H$2*EXP(-$Q$2*$Q$2/2*W$6)*EXP($Q$2*SQRT(W$6)*$D19) -> 9.3696225 | X19: =MAX(0,(W19-$X$7)) -> 3.6196225 | Y19: =$H$2*EXP(-$Q$2*$Q$2/2*Y$6)*EXP($Q$2*SQRT(Y$6)*$D19) -> 9.4128225 | Z19: =MAX(0,(Y19-$Z$7)) -> 3.6628225 | AA19: =$H$2*EXP(-$Q$2*$Q$2/2*AA$6)*EXP($Q$2*SQRT(AA$6)*$D19) -> 9.4521207 | AB19: =MAX(0,(AA19-$AB$7)) -> 3.7021207 | AC19: =$H$2*EXP(-$Q$2*$Q$2/2*AC$6)*EXP($Q$2*SQRT(AC$6)*$D19) -> 9.4904547 | AD19: =MAX(0,(AC19-$AD$7)) -> 3.7404547 | AE19: =$H$2*EXP(-$Q$2*$Q$2/2*AE$6)*EXP($Q$2*SQRT(AE$6)*$D19) -> 9.5267379 | AF19: =MAX((AE19-$AF$7),0) -> 3.7767379 | AG19: =$H$2*EXP(-$Q$2*$Q$2/2*AG$6)*EXP($Q$2*SQRT(AG$6)*$D19) -> 9.5579279 | AH19: =MAX((AG19-$AH$7),0) -> 3.8079279 | AI19: =$H$2*EXP(-$Q$2*$Q$2/2*AI$6)*EXP($Q$2*SQRT(AI$6)*$D19) -> 9.5908756 | AJ19: =MAX(0,(AI19-$AJ$7)) -> 3.8408756 | AK19: =$H$2*EXP(-$Q$2*$Q$2/2*AK$6)*EXP($Q$2*SQRT(AK$6)*$D19) -> 9.6213155 | AL19: =MAX(0,(AK19-$AL$7)) -> 3.8713155 | AM19: =$H$2*EXP(-$Q$2*$Q$2/2*AM$6)*EXP($Q$2*SQRT(AM$6)*$D19) -> 9.6514052 | AN19: =MAX(0,(AM19-$AN$7)) -> 3.9014052 | AO19: =$H$2*EXP(-$Q$2*$Q$2/2*AO$6)*EXP($Q$2*SQRT(AO$6)*$D19) -> 9.679309 | AP19: =MAX(0,(AO19-$AP$7)) -> 3.929309 | AQ19: =$H$2*EXP(-$Q$2*$Q$2/2*AQ$6)*EXP($Q$2*SQRT(AQ$6)*$D19) -> 9.7069834 | AR19: =MAX(0,(AQ19-$AR$7)) -> 3.9569834 | AS19: =$H$2*EXP(-$Q$2*$Q$2/2*AS$6)*EXP($Q$2*SQRT(AS$6)*$D19) -> 9.7335645 | AT19: =MAX(0,(AS19-$AT$7)) -> 3.9835645
... A22: 5.1408333 | B22: 15 | C22: =SQRT($E$2)*B22-INT(SQRT($E$2)*B22) -> 0.68626967 | D22: =_xlfn.NORM.S.INV(C22) -> 0.48530407 | E22: =$H$2*EXP(-$Q$2*$Q$2/2*E$6)*EXP($Q$2*SQRT(E$6)*$D22) -> 8.60992 | F22: =MAX((E22-$F$7),0) -> 2.85992 | G22: =$H$2*EXP(-$Q$2*$Q$2/2*G$6)*EXP($Q$2*SQRT(G$6)*$D22) -> 8.709986 | H22: =MAX(0,(G22-$H$7)) -> 2.959986 | I22: =$H$2*EXP(-$Q$2*$Q$2/2*I$6)*EXP($Q$2*SQRT(I$6)*$D22) -> 8.7742073 | J22: =MAX(0,(I22-$J$7)) -> 3.0242073 | K22: =$H$2*EXP(-$Q$2*$Q$2/2*K$6)*EXP($Q$2*SQRT(K$6)*$D22) -> 8.8312876 | L22: =MAX(0,(K22-$L$7)) -> 3.0812876 | M22: =$H$2*EXP(-$Q$2*$Q$2/2*M$6)*EXP($Q$2*SQRT(M$6)*$D22) -> 8.8777266 | N22: =MAX(0,(M22-$N$7)) -> 3.1277266 | O22: =$H$2*EXP(-$Q$2*$Q$2/2*O$6)*EXP($Q$2*SQRT(O$6)*$D22) -> 8.9193892 | P22: =MAX(0,(O22-$P$7)) -> 3.1693892 | Q22: =$H$2*EXP(-$Q$2*$Q$2/2*Q$6)*EXP($Q$2*SQRT(Q$6)*$D22) -> 8.955113 | R22: =MAX((Q22-$R$7),0) -> 3.205113 | S22: =$H$2*EXP(-$Q$2*$Q$2/2*S$6)*EXP($Q$2*SQRT(S$6)*$D22) -> 8.9882984 | T22: =MAX(0,(S22-$T$7)) -> 3.2382984 | U22: =$H$2*EXP(-$Q$2*$Q$2/2*U$6)*EXP($Q$2*SQRT(U$6)*$D22) -> 9.0184009 | V22: =MAX(0,(U22-$V$7)) -> 3.2684009 | W22: =$H$2*EXP(-$Q$2*$Q$2/2*W$6)*EXP($Q$2*SQRT(W$6)*$D22) -> 9.045083 | X22: =MAX(0,(W22-$X$7)) -> 3.295083 | Y22: =$H$2*EXP(-$Q$2*$Q$2/2*Y$6)*EXP($Q$2*SQRT(Y$6)*$D22) -> 9.070499 | Z22: =MAX(0,(Y22-$Z$7)) -> 3.320499 | AA22: =$H$2*EXP(-$Q$2*$Q$2/2*AA$6)*EXP($Q$2*SQRT(AA$6)*$D22) -> 9.093287 | AB22: =MAX(0,(AA22-$AB$7)) -> 3.343287 | AC22: =$H$2*EXP(-$Q$2*$Q$2/2*AC$6)*EXP($Q$2*SQRT(AC$6)*$D22) -> 9.1151964 | AD22: =MAX(0,(AC22-$AD$7)) -> 3.3651964 | AE22: =$H$2*EXP(-$Q$2*$Q$2/2*AE$6)*EXP($Q$2*SQRT(AE$6)*$D22) -> 9.1356293 | AF22: =MAX((AE22-$AF$7),0) -> 3.3856293 | AG22: =$H$2*EXP(-$Q$2*$Q$2/2*AG$6)*EXP($Q$2*SQRT(AG$6)*$D22) -> 9.1529468 | AH22: =MAX((AG22-$AH$7),0) -> 3.4029468 | AI22: =$H$2*EXP(-$Q$2*$Q$2/2*AI$6)*EXP($Q$2*SQRT(AI$6)*$D22) -> 9.1709807 | AJ22: =MAX(0,(AI22-$AJ$7)) -> 3.4209807 | AK22: =$H$2*EXP(-$Q$2*$Q$2/2*AK$6)*EXP($Q$2*SQRT(AK$6)*$D22) -> 9.1873948 | AL22: =MAX(0,(AK22-$AL$7)) -> 3.4373948 | AM22: =$H$2*EXP(-$Q$2*$Q$2/2*AM$6)*EXP($Q$2*SQRT(AM$6)*$D22) -> 9.2033762 | AN22: =MAX(0,(AM22-$AN$7)) -> 3.4533762 | AO22: =$H$2*EXP(-$Q$2*$Q$2/2*AO$6)*EXP($Q$2*SQRT(AO$6)*$D22) -> 9.2179703 | AP22: =MAX(0,(AO22-$AP$7)) -> 3.4679703 | AQ22: =$H$2*EXP(-$Q$2*$Q$2/2*AQ$6)*EXP($Q$2*SQRT(AQ$6)*$D22) -> 9.2322197 | AR22: =MAX(0,(AQ22-$AR$7)) -> 3.4822197 | AS22: =$H$2*EXP(-$Q$2*$Q$2/2*AS$6)*EXP($Q$2*SQRT(AS$6)*$D22) -> 9.2456863 | AT22: =MAX(0,(AS22-$AT$7)) -> 3.4956863
B23: 16 | C23: =SQRT($E$2)*B23-INT(SQRT($E$2)*B23) -> 0.33202098 | D23: =_xlfn.NORM.S.INV(C23) -> -0.43433946 | E23: =$H$2*EXP(-$Q$2*$Q$2/2*E$6)*EXP($Q$2*SQRT(E$6)*$D23) -> 8.1939252 | F23: =MAX((E23-$F$7),0) -> 2.4439252 | G23: =$H$2*EXP(-$Q$2*$Q$2/2*G$6)*EXP($Q$2*SQRT(G$6)*$D23) -> 8.0808944 | H23: =MAX(0,(G23-$H$7)) -> 2.3308944 | I23: =$H$2*EXP(-$Q$2*$Q$2/2*I$6)*EXP($Q$2*SQRT(I$6)*$D23) -> 8.0022473 | J23: =MAX(0,(I23-$J$7)) -> 2.2522473 | K23: =$H$2*EXP(-$Q$2*$Q$2/2*K$6)*EXP($Q$2*SQRT(K$6)*$D23) -> 7.9277572 | L23: =MAX(0,(K23-$L$7)) -> 2.1777572 | M23: =$H$2*EXP(-$Q$2*$Q$2/2*M$6)*EXP($Q$2*SQRT(M$6)*$D23) -> 7.8635796 | N23: =MAX(0,(M23-$N$7)) -> 2.1135796 | O23: =$H$2*EXP(-$Q$2*$Q$2/2*O$6)*EXP($Q$2*SQRT(O$6)*$D23) -> 7.8029575 | P23: =MAX(0,(O23-$P$7)) -> 2.0529575 | Q23: =$H$2*EXP(-$Q$2*$Q$2/2*Q$6)*EXP($Q$2*SQRT(Q$6)*$D23) -> 7.7484365 | R23: =MAX((Q23-$R$7),0) -> 1.9984365 | S23: =$H$2*EXP(-$Q$2*$Q$2/2*S$6)*EXP($Q$2*SQRT(S$6)*$D23) -> 7.6954697 | T23: =MAX(0,(S23-$T$7)) -> 1.9454697 | U23: =$H$2*EXP(-$Q$2*$Q$2/2*U$6)*EXP($Q$2*SQRT(U$6)*$D23) -> 7.6452966 | V23: =MAX(0,(U23-$V$7)) -> 1.8952966 | W23: =$H$2*EXP(-$Q$2*$Q$2/2*W$6)*EXP($Q$2*SQRT(W$6)*$D23) -> 7.5989668 | X23: =MAX(0,(W23-$X$7)) -> 1.8489668 | Y23: =$H$2*EXP(-$Q$2*$Q$2/2*Y$6)*EXP($Q$2*SQRT(Y$6)*$D23) -> 7.5530554 | Z23: =MAX(0,(Y23-$Z$7)) -> 1.8030554 | AA23: =$H$2*EXP(-$Q$2*$Q$2/2*AA$6)*EXP($Q$2*SQRT(AA$6)*$D23) -> 7.5102756 | AB23: =MAX(0,(AA23-$AB$7)) -> 1.7602756 | AC23: =$H$2*EXP(-$Q$2*$Q$2/2*AC$6)*EXP($Q$2*SQRT(AC$6)*$D23) -> 7.4675694 | AD23: =MAX(0,(AC23-$AD$7)) -> 1.7175694 | AE23: =$H$2*EXP(-$Q$2*$Q$2/2*AE$6)*EXP($Q$2*SQRT(AE$6)*$D23) -> 7.4262184 | AF23: =MAX((AE23-$AF$7),0) -> 1.6762184 | AG23: =$H$2*EXP(-$Q$2*$Q$2/2*AG$6)*EXP($Q$2*SQRT(AG$6)*$D23) -> 7.3899168 | AH23: =MAX((AG23-$AH$7),0) -> 1.6399168 | AI23: =$H$2*EXP(-$Q$2*$Q$2/2*AI$6)*EXP($Q$2*SQRT(AI$6)*$D23) -> 7.350777 | AJ23: =MAX(0,(AI23-$AJ$7)) -> 1.600777 | AK23: =$H$2*EXP(-$Q$2*$Q$2/2*AK$6)*EXP($Q$2*SQRT(AK$6)*$D23) -> 7.3138608 | AL23: =MAX(0,(AK23-$AL$7)) -> 1.5638608 | AM23: =$H$2*EXP(-$Q$2*$Q$2/2*AM$6)*EXP($Q$2*SQRT(AM$6)*$D23) -> 7.276624 | AN23: =MAX(0,(AM23-$AN$7)) -> 1.526624 | AO23: =$H$2*EXP(-$Q$2*$Q$2/2*AO$6)*EXP($Q$2*SQRT(AO$6)*$D23) -> 7.2414002 | AP23: =MAX(0,(AO23-$AP$7)) -> 1.4914002 | AQ23: =$H$2*EXP(-$Q$2*$Q$2/2*AQ$6)*EXP($Q$2*SQRT(AQ$6)*$D23) -> 7.2057791 | AR23: =MAX(0,(AQ23-$AR$7)) -> 1.4557791 | AS23: =$H$2*EXP(-$Q$2*$Q$2/2*AS$6)*EXP($Q$2*SQRT(AS$6)*$D23) -> 7.1708918 | AT23: =MAX(0,(AS23-$AT$7)) -> 1.4208918
B24: 17 | C24: =SQRT($E$2)*B24-INT(SQRT($E$2)*B24) -> 0.97777229 | D24: =_xlfn.NORM.S.INV(C24) -> 2.0097711 | E24: =$H$2*EXP(-$Q$2*$Q$2/2*E$6)*EXP($Q$2*SQRT(E$6)*$D24) -> 9.3465399 | F24: =MAX((E24-$F$7),0) -> 3.5965399 | G24: =$H$2*EXP(-$Q$2*$Q$2/2*G$6)*EXP($Q$2*SQRT(G$6)*$D24) -> 9.8625217 | H24: =MAX(0,(G24-$H$7)) -> 4.1125217 | I24: =$H$2*EXP(-$Q$2*$Q$2/2*I$6)*EXP($Q$2*SQRT(I$6)*$D24) -> 10.221344 | J24: =MAX(0,(I24-$J$7)) -> 4.4713439 | K24: =$H$2*EXP(-$Q$2*$Q$2/2*K$6)*EXP($Q$2*SQRT(K$6)*$D24) -> 10.56149 | L24: =MAX(0,(K24-$L$7)) -> 4.8114904 | M24: =$H$2*EXP(-$Q$2*$Q$2/2*M$6)*EXP($Q$2*SQRT(M$6)*$D24) -> 10.855013 | N24: =MAX(0,(M24-$N$7)) -> 5.1050132 | O24: =$H$2*EXP(-$Q$2*$Q$2/2*O$6)*EXP($Q$2*SQRT(O$6)*$D24) -> 11.132837 | P24: =MAX(0,(O24-$P$7)) -> 5.3828366 | Q24: =$H$2*EXP(-$Q$2*$Q$2/2*Q$6)*EXP($Q$2*SQRT(Q$6)*$D24) -> 11.383278 | R24: =MAX((Q24-$R$7),0) -> 5.6332777 | S24: =$H$2*EXP(-$Q$2*$Q$2/2*S$6)*EXP($Q$2*SQRT(S$6)*$D24) -> 11.62719 | T24: =MAX(0,(S24-$T$7)) -> 5.8771896 | U24: =$H$2*EXP(-$Q$2*$Q$2/2*U$6)*EXP($Q$2*SQRT(U$6)*$D24) -> 11.85886 | V24: =MAX(0,(U24-$V$7)) -> 6.1088602 | W24: =$H$2*EXP(-$Q$2*$Q$2/2*W$6)*EXP($Q$2*SQRT(W$6)*$D24) -> 12.073375 | X24: =MAX(0,(W24-$X$7)) -> 6.3233751 | Y24: =$H$2*EXP(-$Q$2*$Q$2/2*Y$6)*EXP($Q$2*SQRT(Y$6)*$D24) -> 12.286556 | Z24: =MAX(0,(Y24-$Z$7)) -> 6.5365565 | AA24: =$H$2*EXP(-$Q$2*$Q$2/2*AA$6)*EXP($Q$2*SQRT(AA$6)*$D24) -> 12.485773 | AB24: =MAX(0,(AA24-$AB$7)) -> 6.7357731 | AC24: =$H$2*EXP(-$Q$2*$Q$2/2*AC$6)*EXP($Q$2*SQRT(AC$6)*$D24) -> 12.685233 | AD24: =MAX(0,(AC24-$AD$7)) -> 6.935233 | AE24: =$H$2*EXP(-$Q$2*$Q$2/2*AE$6)*EXP($Q$2*SQRT(AE$6)*$D24) -> 12.878949 | AF24: =MAX((AE24-$AF$7),0) -> 7.1289492 | AG24: =$H$2*EXP(-$Q$2*$Q$2/2*AG$6)*EXP($Q$2*SQRT(AG$6)*$D24) -> 13.049507 | AH24: =MAX((AG24-$AH$7),0) -> 7.2995066 | AI24: =$H$2*EXP(-$Q$2*$Q$2/2*AI$6)*EXP($Q$2*SQRT(AI$6)*$D24) -> 13.233937 | AJ24: =MAX(0,(AI24-$AJ$7)) -> 7.4839373 | AK24: =$H$2*EXP(-$Q$2*$Q$2/2*AK$6)*EXP($Q$2*SQRT(AK$6)*$D24) -> 13.40842 | AL24: =MAX(0,(AK24-$AL$7)) -> 7.6584202 | AM24: =$H$2*EXP(-$Q$2*$Q$2/2*AM$6)*EXP($Q$2*SQRT(AM$6)*$D24) -> 13.584957 | AN24: =MAX(0,(AM24-$AN$7)) -> 7.8349567 | AO24: =$H$2*EXP(-$Q$2*$Q$2/2*AO$6)*EXP($Q$2*SQRT(AO$6)*$D24) -> 13.752461 | AP24: =MAX(0,(AO24-$AP$7)) -> 8.0024612 | AQ24: =$H$2*EXP(-$Q$2*$Q$2/2*AQ$6)*EXP($Q$2*SQRT(AQ$6)*$D24) -> 13.922376 | AR24: =MAX(0,(AQ24-$AR$7)) -> 8.172376 | AS24: =$H$2*EXP(-$Q$2*$Q$2/2*AS$6)*EXP($Q$2*SQRT(AS$6)*$D24) -> 14.08931 | AT24: =MAX(0,(AS24-$AT$7)) -> 8.3393096
B25: 18 | C25: =SQRT($E$2)*B25-INT(SQRT($E$2)*B25) -> 0.6235236 | D25: =_xlfn.NORM.S.INV(C25) -> 0.31474826 | E25: =$H$2*EXP(-$Q$2*$Q$2/2*E$6)*EXP($Q$2*SQRT(E$6)*$D25) -> 8.5312062 | F25: =MAX((E25-$F$7),0) -> 2.7812062 | G25: =$H$2*EXP(-$Q$2*$Q$2/2*G$6)*EXP($Q$2*SQRT(G$6)*$D25) -> 8.5897256 | H25: =MAX(0,(G25-$H$7)) -> 2.8397256 | I25: =$H$2*EXP(-$Q$2*$Q$2/2*I$6)*EXP($Q$2*SQRT(I$6)*$D25) -> 8.6256196 | J25: =MAX(0,(I25-$J$7)) -> 2.8756196 | K25: =$H$2*EXP(-$Q$2*$Q$2/2*K$6)*EXP($Q$2*SQRT(K$6)*$D25) -> 8.6562721 | L25: =MAX(0,(K25-$L$7)) -> 2.9062721 | M25: =$H$2*EXP(-$Q$2*$Q$2/2*M$6)*EXP($Q$2*SQRT(M$6)*$D25) -> 8.680236 | N25: =MAX(0,(M25-$N$7)) -> 2.930236 | O25: =$H$2*EXP(-$Q$2*$Q$2/2*O$6)*EXP($Q$2*SQRT(O$6)*$D25) -> 8.7009053 | P25: =MAX(0,(O25-$P$7)) -> 2.9509053 | Q25: =$H$2*EXP(-$Q$2*$Q$2/2*Q$6)*EXP($Q$2*SQRT(Q$6)*$D25) -> 8.7179365 | R25: =MAX((Q25-$R$7),0) -> 2.9679365 | S25: =$H$2*EXP(-$Q$2*$Q$2/2*S$6)*EXP($Q$2*SQRT(S$6)*$D25) -> 8.7331259 | T25: =MAX(0,(S25-$T$7)) -> 2.9831259 | U25: =$H$2*EXP(-$Q$2*$Q$2/2*U$6)*EXP($Q$2*SQRT(U$6)*$D25) -> 8.7463253 | V25: =MAX(0,(U25-$V$7)) -> 2.9963253 | W25: =$H$2*EXP(-$Q$2*$Q$2/2*W$6)*EXP($Q$2*SQRT(W$6)*$D25) -> 8.7575198 | X25: =MAX(0,(W25-$X$7)) -> 3.0075198 | Y25: =$H$2*EXP(-$Q$2*$Q$2/2*Y$6)*EXP($Q$2*SQRT(Y$6)*$D25) -> 8.7676992 | Z25: =MAX(0,(Y25-$Z$7)) -> 3.0176992 | AA25: =$H$2*EXP(-$Q$2*$Q$2/2*AA$6)*EXP($Q$2*SQRT(AA$6)*$D25) -> 8.7763872 | AB25: =MAX(0,(AA25-$AB$7)) -> 3.0263872 | AC25: =$H$2*EXP(-$Q$2*$Q$2/2*AC$6)*EXP($Q$2*SQRT(AC$6)*$D25) -> 8.7843123 | AD25: =MAX(0,(AC25-$AD$7)) -> 3.0343123 | AE25: =$H$2*EXP(-$Q$2*$Q$2/2*AE$6)*EXP($Q$2*SQRT(AE$6)*$D25) -> 8.7912903 | AF25: =MAX((AE25-$AF$7),0) -> 3.0412903 | AG25: =$H$2*EXP(-$Q$2*$Q$2/2*AG$6)*EXP($Q$2*SQRT(AG$6)*$D25) -> 8.7968637 | AH25: =MAX((AG25-$AH$7),0) -> 3.0468637 | AI25: =$H$2*EXP(-$Q$2*$Q$2/2*AI$6)*EXP($Q$2*SQRT(AI$6)*$D25) -> 8.8023057 | AJ25: =MAX(0,(AI25-$AJ$7)) -> 3.0523057 | AK25: =$H$2*EXP(-$Q$2*$Q$2/2*AK$6)*EXP($Q$2*SQRT(AK$6)*$D25) -> 8.8069089 | AL25: =MAX(0,(AK25-$AL$7)) -> 3.0569089 | AM25: =$H$2*EXP(-$Q$2*$Q$2/2*AM$6)*EXP($Q$2*SQRT(AM$6)*$D25) -> 8.8110405 | AN25: =MAX(0,(AM25-$AN$7)) -> 3.0610405 | AO25: =$H$2*EXP(-$Q$2*$Q$2/2*AO$6)*EXP($Q$2*SQRT(AO$6)*$D25) -> 8.8144836 | AP25: =MAX(0,(AO25-$AP$7)) -> 3.0644836 | AQ25: =$H$2*EXP(-$Q$2*$Q$2/2*AQ$6)*EXP($Q$2*SQRT(AQ$6)*$D25) -> 8.8175131 | AR25: =MAX(0,(AQ25-$AR$7)) -> 3.0675131 | AS25: =$H$2*EXP(-$Q$2*$Q$2/2*AS$6)*EXP($Q$2*SQRT(AS$6)*$D25) -> 8.8200456 | AT25: =MAX(0,(AS25-$AT$7)) -> 3.0700456
B26: 19 | C26: =SQRT($E$2)*B26-INT(SQRT($E$2)*B26) -> 0.26927491 | D26: =_xlfn.NORM.S.INV(C26) -> -0.61500742 | E26: =$H$2*EXP(-$Q$2*$Q$2/2*E$6)*EXP($Q$2*SQRT(E$6)*$D26) -> 8.1145946 | F26: =MAX((E26-$F$7),0) -> 2.3645946 | G26: =$H$2*EXP(-$Q$2*$Q$2/2*G$6)*EXP($Q$2*SQRT(G$6)*$D26) -> 7.9627534 | H26: =MAX(0,(G26-$H$7)) -> 2.2127534 | I26: =$H$2*EXP(-$Q$2*$Q$2/2*I$6)*EXP($Q$2*SQRT(I$6)*$D26) -> 7.8587703 | J26: =MAX(0,(I26-$J$7)) -> 2.1087703 | K26: =$H$2*EXP(-$Q$2*$Q$2/2*K$6)*EXP($Q$2*SQRT(K$6)*$D26) -> 7.761431 | L26: =MAX(0,(K26-$L$7)) -> 2.011431 | M26: =$H$2*EXP(-$Q$2*$Q$2/2*M$6)*EXP($Q$2*SQRT(M$6)*$D26) -> 7.6784009 | N26: =MAX(0,(M26-$N$7)) -> 1.9284009 | O26: =$H$2*EXP(-$Q$2*$Q$2/2*O$6)*EXP($Q$2*SQRT(O$6)*$D26) -> 7.6006369 | P26: =MAX(0,(O26-$P$7)) -> 1.8506369 | Q26: =$H$2*EXP(-$Q$2*$Q$2/2*Q$6)*EXP($Q$2*SQRT(Q$6)*$D26) -> 7.5312237 | R26: =MAX((Q26-$R$7),0) -> 1.7812237 | S26: =$H$2*EXP(-$Q$2*$Q$2/2*S$6)*EXP($Q$2*SQRT(S$6)*$D26) -> 7.4642434 | T26: =MAX(0,(S26-$T$7)) -> 1.7142434 | U26: =$H$2*EXP(-$Q$2*$Q$2/2*U$6)*EXP($Q$2*SQRT(U$6)*$D26) -> 7.4011916 | V26: =MAX(0,(U26-$V$7)) -> 1.6511916 | W26: =$H$2*EXP(-$Q$2*$Q$2/2*W$6)*EXP($Q$2*SQRT(W$6)*$D26) -> 7.3432988 | X26: =MAX(0,(W26-$X$7)) -> 1.5932988 | Y26: =$H$2*EXP(-$Q$2*$Q$2/2*Y$6)*EXP($Q$2*SQRT(Y$6)*$D26) -> 7.28623 | Z26: =MAX(0,(Y26-$Z$7)) -> 1.53623 | AA26: =$H$2*EXP(-$Q$2*$Q$2/2*AA$6)*EXP($Q$2*SQRT(AA$6)*$D26) -> 7.2333152 | AB26: =MAX(0,(AA26-$AB$7)) -> 1.4833152 | AC26: =$H$2*EXP(-$Q$2*$Q$2/2*AC$6)*EXP($Q$2*SQRT(AC$6)*$D26) -> 7.1807354 | AD26: =MAX(0,(AC26-$AD$7)) -> 1.4307354 | AE26: =$H$2*EXP(-$Q$2*$Q$2/2*AE$6)*EXP($Q$2*SQRT(AE$6)*$D26) -> 7.13005 | AF26: =MAX((AE26-$AF$7),0) -> 1.38005 | AG26: =$H$2*EXP(-$Q$2*$Q$2/2*AG$6)*EXP($Q$2*SQRT(AG$6)*$D26) -> 7.0857322 | AH26: =MAX((AG26-$AH$7),0) -> 1.3357322 | AI26: =$H$2*EXP(-$Q$2*$Q$2/2*AI$6)*EXP($Q$2*SQRT(AI$6)*$D26) -> 7.0381321 | AJ26: =MAX(0,(AI26-$AJ$7)) -> 1.2881321 | AK26: =$H$2*EXP(-$Q$2*$Q$2/2*AK$6)*EXP($Q$2*SQRT(AK$6)*$D26) -> 6.9934059 | AL26: =MAX(0,(AK26-$AL$7)) -> 1.2434059 | AM26: =$H$2*EXP(-$Q$2*$Q$2/2*AM$6)*EXP($Q$2*SQRT(AM$6)*$D26) -> 6.9484542 | AN26: =MAX(0,(AM26-$AN$7)) -> 1.1984542 | AO26: =$H$2*EXP(-$Q$2*$Q$2/2*AO$6)*EXP($Q$2*SQRT(AO$6)*$D26) -> 6.9060804 | AP26: =MAX(0,(AO26-$AP$7)) -> 1.1560804 | AQ26: =$H$2*EXP(-$Q$2*$Q$2/2*AQ$6)*EXP($Q$2*SQRT(AQ$6)*$D26) -> 6.8633715 | AR26: =MAX(0,(AQ26-$AR$7)) -> 1.1133715 | AS26: =$H$2*EXP(-$Q$2*$Q$2/2*AS$6)*EXP($Q$2*SQRT(AS$6)*$D26) -> 6.8216792 | AT26: =MAX(0,(AS26-$AT$7)) -> 1.0716792
